Workbook

Sheet обложка
A3: ФЕДЕРАЛЬНАЯ СЛУЖБА ГОСУДАРСТВЕННОЙ СТАТИСТИКИ
B13: ЕСТЕСТВЕННОЕ ДВИЖЕНИЕ НАСЕЛЕНИЯ
B15: РОССИЙСКОЙ ФЕДЕРАЦИИ
B17: за 2016 год
B21: (Статистический бюллетень)
B31: МОСКВА 2017 г.

Sheet титул
A3: ФЕДЕРАЛЬНАЯ СЛУЖБА ГОСУДАРСТВЕННОЙ СТАТИСТИКИ
B13: ЕСТЕСТВЕННОЕ ДВИЖЕНИЕ НАСЕЛЕНИЯ
B15: РОССИЙСКОЙ ФЕДЕРАЦИИ
B17: за 2016 год
B21: (Статистический бюллетень)
B31: МОСКВА 2017 г.

Sheet содержание
B2: № табл. | C2: СОДЕРЖАНИЕ | D2: стр.
C4: Предисловие…………………………………………………………………………………………………………...………………………………..……………………………….. | D4: 3
B5: 1 | C5: Общие итоги естественного движения населения в Российской Федерации……………………………………….……………………………………… | D5: 5
B6: 2 | C6: Родившиеся, умершие и естественный прирост населения по субъектам Российской Федерации………………………………...…………………… | D6: 6
B7: 3 | C7: Общие коэффициенты рождаемости, смертности, естественного прироста населения по субъектам Российской Федерации……………..… | D7: 9
B8: 4 | C8: Родившиеся живыми у женщин, не состоявших в зарегистрированном браке, по субъектам Российской Федерации……………….…… | D8: 12
B9: 5 | C9: Родившиеся вне брака по возрасту матери по субъектам Российской Федерации в 2016 году……………………………………………………….…….. | D9: 15
B10: 6 | C10: Число родившихся живыми по возрасту матери и очередности рождения в Российской Федерации в 2016 году……………………………...……… | D10: 18
B11: 7 | C11: Число родившихся живыми по возрасту и образованию матери в 2016 году…………………………………………………………………………..………. | D11: 19
B12: 8 | C12: Смертность населения по основным классам и отдельным причинам смерти……………………………………………………………………..…...….. | D12: 20
B13: 9 | C13: Умершие по основным классам причин смерти по субъектам Российской Федерации…………………………………………………….……………. | D13: 22
B14: 10 | C14: Cмертность населения по основным классам причин смерти по субъектам Российской Федерации………………………………………..…………….. | D14: 25
B15: 11 | C15: Число умерших от внешних причин смерти по субъектам Российской Федерации……………………………………………………………...…………… | D15: 28
B16: 12 | C16: Смертность населения от внешних причин смерти по субъектам Российской Федерации…………………………………………………………..……………. | D16: 31
... B25: 21 | C25: Общие коэффициенты брачности и разводимости по субъектам Российской Федерации………………………………………………………….……. | D25: 54

Sheet предисловие

Sheet ТАБ_1 
A1: 1. ОБЩИЕ ИТОГИ ЕСТЕСТВЕННОГО ДВИЖЕНИЯ НАСЕЛЕНИЯ
A2: В РОССИЙСКОЙ ФЕДЕРАЦИИ
B4: Абсолютные данные | E4: На 1000 человек населения
B5: 2016г. | C5: 2015г. | D5: Прирост, снижение / - / | E5: 2016г. | F5: 2015г.
A6: Родившихся | B6: 1888729 | C6: 1940579 | D6: =B6-C6 -> -51850 | E6: 12.9 | F6: 13.3
A7: Умерших | B7: 1891015 | C7: 1908541 | D7: =B7-C7 -> -17526 | E7: 12.9 | F7: 13
A8: из них детей в возрасте до 1 года | B8: 11428 | C8: 12664 | D8: =B8-C8 -> -1236 | E8: 6,01) | F8: 6,51)
A9: Естественный прирост, (убыль) | B9: -2286 | C9: 32038 | D9: Х | E9: -0.01 | F9: 0.3
A10: Браков | B10: 985836 | C10: 1161068 | D10: =B10-C10 -> -175232 | E10: 6.7 | F10: 7.9
A11: Разводов | B11: 608336 | C11: 611646 | D11: =B11-C11 -> -3310 | E11: 4.1 | F11: 4.2
A13: 1) Рассчитывается на 1000 родившихся живыми.

Sheet ТАБ_2
A1: 2. РОДИВШИЕСЯ, УМЕРШИЕ И ЕСТЕСТВЕННЫЙ ПРИРОСТ НАСЕЛЕНИЯ ПО СУБЪЕКТАМ РОССИЙСКОЙ ФЕДЕРАЦИИ
B3: Число родившихся | D3: Прирост, снижение /-/ | E3: Число умерших | G3: Прирост, снижение /-/ | H3: Естественный прирост, убыль (-)
B5: 2016г. | C5: 2015г. | E5: 2016г. | F5: 2015г. | H5: 2016г. | I5: 2015г.
A6: РОССИЙСКАЯ ФЕДЕРАЦИЯ | B6: 1888729 | C6: 1940579 | D6: =B6-C6 -> -51850 | E6: 1891015 | F6: 1908541 | G6: =E6-F6 -> -17526 | H6: -2286 | I6: 32038
A7: Центральный федеральный округ | B7: 455865 | C7: 456969 | D7: =B7-C7 -> -1104 | E7: 526885 | F7: 525885 | G7: =E7-F7 -> 1000 | H7: -71020 | I7: -68916
A8: Белгородская область | B8: 17247 | C8: 17773 | D8: =B8-C8 -> -526 | E8: 21586 | F8: 21490 | G8: =E8-F8 -> 96 | H8: -4339 | I8: -3717
A9: Брянская область | B9: 13364 | C9: 14070 | D9: =B9-C9 -> -706 | E9: 19042 | F9: 19447 | G9: =E9-F9 -> -405 | H9: -5678 | I9: -5377
A10: Владимирская область | B10: 15654 | C10: 16214 | D10: =B10-C10 -> -560 | E10: 22947 | F10: 23117 | G10: =E10-F10 -> -170 | H10: -7293 | I10: -6903
A11: Воронежская область | B11: 24936 | C11: 25801 | D11: =B11-C11 -> -865 | E11: 35551 | F11: 35684 | G11: =E11-F11 -> -133 | H11: -10615 | I11: -9883
A12: Ивановская область | B12: 11147 | C12: 11753 | D12: =B12-C12 -> -606 | E12: 16489 | F12: 16584 | G12: =E12-F12 -> -95 | H12: -5342 | I12: -4831
A13: Калужская область | B13: 12252 | C13: 12774 | D13: =B13-C13 -> -522 | E13: 15210 | F13: 15200 | G13: =E13-F13 -> 10 | H13: -2958 | I13: -2426
A14: Костромская область | B14: 7829 | C14: 8151 | D14: =B14-C14 -> -322 | E14: 10148 | F14: 10454 | G14: =E14-F14 -> -306 | H14: -2319 | I14: -2303
A15: Курская область | B15: 12403 | C15: 13032 | D15: =B15-C15 -> -629 | E15: 18015 | F15: 18205 | G15: =E15-F15 -> -190 | H15: -5612 | I15: -5173
A16: Липецкая область | B16: 13094 | C16: 13428 | D16: =B16-C16 -> -334 | E16: 17538 | F16: 17725 | G16: =E16-F16 -> -187 | H16: -4444 | I16: -4297
A17: Московская область | B17: 96643 | C17: 94186 | D17: =B17-C17 -> 2457 | E17: 95561 | F17: 94210 | G17: =E17-F17 -> 1351 | H17: 1082 | I17: -24
... A101: Чукотский автономный округ | B101: 679 | C101: 685 | D101: =B101-C101 -> -6 | E101: 498 | F101: 479 | G101: =E101-F101 -> 19 | H101: 181 | I101: 206

Sheet ТАБ_3
A1: 3. ОБЩИЕ КОЭФФИЦИЕНТЫ РОЖДАЕМОСТИ, СМЕРТНОСТИ, ЕСТЕСТВЕННОГО ПРИРОСТА НАСЕЛЕНИЯ
A2: ПО СУБЪЕКТАМ РОССИЙСКОЙ ФЕДЕРАЦИИ
A3: ( на 1000 человек населения )
B4: Число родившихся | D4: Число умерших | F4: Естественный прирост, убыль ( - )
B6: 2016г. | C6: 2015г. | D6: 2016г. | E6: 2015г. | F6: 2016г. | G6: 2015г.
A7: РОССИЙСКАЯ ФЕДЕРАЦИЯ | B7: 12.9 | C7: 13.3 | D7: 12.9 | E7: 13 | F7: -0.01 | G7: 0.3
A8: Центральный федеральный округ | B8: 11.6 | C8: 11.7 | D8: 13.5 | E8: 13.5 | F8: -1.9 | G8: -1.8
A9: Белгородская область | B9: 11.1 | C9: 11.5 | D9: 13.9 | E9: 13.9 | F9: -2.8 | G9: -2.4
A10: Брянская область | B10: 10.9 | C10: 11.4 | D10: 15.6 | E10: 15.8 | F10: -4.7 | G10: -4.4
A11: Владимирская область | B11: 11.2 | C11: 11.6 | D11: 16.5 | E11: 16.5 | F11: -5.3 | G11: -4.9
A12: Воронежская область | B12: 10.7 | C12: 11.1 | D12: 15.2 | E12: 15.3 | F12: -4.5 | G12: -4.2
A13: Ивановская область | B13: 10.9 | C13: 11.4 | D13: 16.1 | E13: 16 | F13: -5.2 | G13: -4.6
A14: Калужская область | B14: 12.1 | C14: 12.6 | D14: 15 | E14: 15 | F14: -2.9 | G14: -2.4
A15: Костромская область | B15: 12 | C15: 12.5 | D15: 15.6 | E15: 16 | F15: -3.6 | G15: -3.5
A16: Курская область | B16: 11.1 | C16: 11.6 | D16: 16.1 | E16: 16.3 | F16: -5 | G16: -4.7
A17: Липецкая область | B17: 11.3 | C17: 11.6 | D17: 15.2 | E17: 15.3 | F17: -3.9 | G17: -3.7
A18: Московская область | B18: 13.1 | C18: 12.9 | D18: 13 | E18: 13 | F18: 0.1 | G18: -0.1
... A39: г.Санкт-Петербург | B39: 13.8 | C39: 13.6 | D39: 11.7 | E39: 11.9 | F39: 2.1 | G39: 1.7
A40: Южный федеральный округ | B40: 12.3 | C40: 12.8 | D40: 13.5 | E40: 13.6 | F40: -1.2 | G40: =C40-E40 -> -0.8
A41: Республика Адыгея | B41: 12 | C41: 12.5 | D41: 12.9 | E41: 13 | F41: -0.9 | G41: -0.5
A42: Республика Калмыкия | B42: 12.4 | C42: 13.6 | D42: 9.8 | E42: 9.8 | F42: 2.6 | G42: 3.8
A43: Республика Крым | B43: 12 | C43: 12.6 | D43: 15.2 | E43: 15.3 | F43: -3.2 | G43: -2.7
A44: Краснодарский край | B44: 13.2 | C44: 13.5 | D44: 12.9 | E44: 13 | F44: 0.3 | G44: 0.5
A45: Астраханская область | B45: 14 | C45: 14.5 | D45: 12 | E45: 12.3 | F45: 2 | G45: 2.2
A46: Волгоградская область | B46: 11.2 | C46: 11.5 | D46: 13.7 | E46: 13.8 | F46: -2.5 | G46: -2.3
A47: Ростовская область | B47: 11.6 | C47: 12.1 | D47: 13.9 | E47: 13.9 | F47: -2.3 | G47: -1.8
A48: г.Севастополь | B48: 12.7 | C48: 13.5 | D48: 13.9 | E48: 14.9 | F48: -1.2 | G48: -1.4
A49: Северо-Кавказский федеральный округ | B49: 15.9 | C49: 16.6 | D49: 7.8 | E49: 7.9 | F49: 8.1 | G49: 8.7
A50: Республика Дагестан | B50: 17.5 | C50: 18.3 | D50: 5.2 | E50: 5.4 | F50: 12.3 | G50: 12.9
A51: Республика Ингушетия | B51: 16.3 | C51: 18.5 | D51: 3.3 | E51: 3.3 | F51: 13 | G51: 15.2
A52: Кабардино-Балкарская Республика | B52: 14 | C52: 14.6 | D52: 8.6 | E52: 8.8 | F52: 5.4 | G52: 5.8
... A102: Чукотский автономный округ | B102: 13.6 | C102: 13.6 | D102: 10 | E102: 9.5 | F102: 3.6 | G102: 4.1

Sheet ТАБ_4
A1: 4. РОДИВШИЕСЯ ЖИВЫМИ У ЖЕНЩИН, НЕ СОСТОЯВШИХ В ЗАРЕГИСТРИРОВАННОМ БРАКЕ,
A2: ПО СУБЪЕКТАМ РОССИЙСКОЙ ФЕДЕРАЦИИ
B4: 2016г. | D4: 2015г.
B5: всего родившихся у женщин вне брака | C5: % к общему числу родившихся | D5: всего родившихся у женщин вне брака | E5: % к общему числу родившихся
A6: РОССИЙСКАЯ ФЕДЕРАЦИЯ | B6: 397588 | C6: =ROUND(B6/ТАБ_2!B6*100,1) -> 21.1 | D6: 419443 | E6: =ТАБ_4!D6/ТАБ_2!C6*100 -> 21.614322
A7: Центральный федеральный округ | B7: 84728 | C7: =ROUND(B7/ТАБ_2!B7*100,1) -> 18.6 | D7: 86578 | E7: =ТАБ_4!D7/ТАБ_2!C7*100 -> 18.946143
A8: Белгородская область | B8: 2470 | C8: =ROUND(B8/ТАБ_2!B8*100,1) -> 14.3 | D8: 2572 | E8: =ТАБ_4!D8/ТАБ_2!C8*100 -> 14.471389
A9: Брянская область | B9: 2406 | C9: =ROUND(B9/ТАБ_2!B9*100,1) -> 18 | D9: 2597 | E9: =ТАБ_4!D9/ТАБ_2!C9*100 -> 18.457711
A10: Владимирская область | B10: 3060 | C10: =ROUND(B10/ТАБ_2!B10*100,1) -> 19.5 | D10: 3294 | E10: =ТАБ_4!D10/ТАБ_2!C10*100 -> 20.315776
A11: Воронежская область | B11: 3963 | C11: =ROUND(B11/ТАБ_2!B11*100,1) -> 15.9 | D11: 4259 | E11: =ТАБ_4!D11/ТАБ_2!C11*100 -> 16.507112
A12: Ивановская область | B12: 2416 | C12: =ROUND(B12/ТАБ_2!B12*100,1) -> 21.7 | D12: 2628 | E12: =ТАБ_4!D12/ТАБ_2!C12*100 -> 22.360248
A13: Калужская область | B13: 2484 | C13: =ROUND(B13/ТАБ_2!B13*100,1) -> 20.3 | D13: 2762 | E13: =ТАБ_4!D13/ТАБ_2!C13*100 -> 21.622045
A14: Костромская область | B14: 1381 | C14: =ROUND(B14/ТАБ_2!B14*100,1) -> 17.6 | D14: 1453 | E14: =ТАБ_4!D14/ТАБ_2!C14*100 -> 17.826034
A15: Курская область | B15: 2188 | C15: =ROUND(B15/ТАБ_2!B15*100,1) -> 17.6 | D15: 2375 | E15: =ТАБ_4!D15/ТАБ_2!C15*100 -> 18.224371
A16: Липецкая область | B16: 2144 | C16: =ROUND(B16/ТАБ_2!B16*100,1) -> 16.4 | D16: 2329 | E16: =ТАБ_4!D16/ТАБ_2!C16*100 -> 17.344355
A17: Московская область | B17: 18347 | C17: =ROUND(B17/ТАБ_2!B17*100,1) -> 19 | D17: 18072 | E17: =ТАБ_4!D17/ТАБ_2!C17*100 -> 19.187565
... A101: Чукотский автономный округ | B101: 265 | C101: =ROUND(B101/ТАБ_2!B101*100,1) -> 39 | D101: 275 | E101: =ТАБ_4!D101/ТАБ_2!C101*100 -> 40.145985

Sheet ТАБ_5
A1: 5. РОДИВШИЕСЯ ВНЕ БРАКА ПО ВОЗРАСТУ МАТЕРИ
A2: ПО СУБЪЕКТАМ РОССИЙСКОЙ ФЕДЕРАЦИИ ЗА 2016 ГОД
B4: 14 и моложе | C4: 15-19 | D4: 20-24 | E4: 25-29 | F4: 30-34 | G4: 35-39 | H4: 40-44 | I4: 45-49 | J4: 50-54 | K4: 55 и более | L4: неиз-вестно
A5: РОССИЙСКАЯ ФЕДЕРАЦИЯ | B5: 286 | C5: 34232 | D5: 80953 | E5: 109028 | F5: 99148 | G5: 58580 | H5: 14303 | I5: 787 | J5: 69 | K5: 13 | L5: 189
A6: Центральный федеральный округ | B6: 66 | C6: 5432 | D6: 14941 | E6: 23357 | F6: 22754 | G6: 14102 | H6: 3706 | I6: 234 | J6: 29 | K6: 3 | L6: 104
A7: Белгородская область | B7: 3 | C7: 199 | D7: 487 | E7: 665 | F7: 625 | G7: 391 | H7: 94 | I7: 4 | J7: 0 | K7: 0 | L7: 2
A8: Брянская область | B8: 0 | C8: 223 | D8: 512 | E8: 651 | F8: 570 | G8: 360 | H8: 87 | I8: 3 | J8: 0 | K8: 0 | L8: 0
A9: Владимирская область | B9: 7 | C9: 272 | D9: 537 | E9: 870 | F9: 788 | G9: 480 | H9: 100 | I9: 3 | J9: 0 | K9: 0 | L9: 3
A10: Воронежская область | B10: 8 | C10: 369 | D10: 777 | E10: 1074 | F10: 994 | G10: 606 | H10: 126 | I10: 6 | J10: 1 | K10: 0 | L10: 2
A11: Ивановская область | B11: 4 | C11: 197 | D11: 458 | E11: 686 | F11: 609 | G11: 369 | H11: 91 | I11: 2 | J11: 0 | K11: 0 | L11: 0
A12: Калужская область | B12: 4 | C12: 206 | D12: 495 | E12: 700 | F12: 651 | G12: 346 | H12: 81 | I12: 1 | J12: 0 | K12: 0 | L12: 0
A13: Костромская область | B13: 2 | C13: 127 | D13: 255 | E13: 359 | F13: 380 | G13: 215 | H13: 41 | I13: 1 | J13: 0 | K13: 0 | L13: 1
A14: Курская область | B14: 3 | C14: 206 | D14: 480 | E14: 583 | F14: 535 | G14: 290 | H14: 85 | I14: 6 | J14: 0 | K14: 0 | L14: 0
A15: Липецкая область | B15: 4 | C15: 201 | D15: 433 | E15: 605 | F15: 536 | G15: 293 | H15: 68 | I15: 4 | J15: 0 | K15: 0 | L15: 0
A16: Московская область | B16: 7 | C16: 1105 | D16: 3324 | E16: 5127 | F16: 4886 | G16: 3049 | H16: 756 | I16: 42 | J16: 9 | K16: 1 | L16: 41
... A100: Чукотский автономный округ | B100: 2 | C100: 47 | D100: 83 | E100: 60 | F100: 44 | G100: 20 | H100: 7 | I100: 2 | J100: 0 | K100: 0 | L100: 0

Sheet ТАБ_6
A1: 6. ЧИСЛО РОДИВШИХСЯ ЖИВЫМИ ПО ВОЗРАСТУ МАТЕРИ И ОЧЕРЕДНОСТИ РОЖДЕНИЯ
A2: В РОССИЙСКОЙ ФЕДЕРАЦИИ В 2016 ГОДУ
A4: Возраст матери (лет) | B4: Всего родившихся живыми | C4: в том числе по очередности рождения ребенка:
C5: первый | D5: второй | E5: третий | F5: четвертый | G5: пятый и более | H5: неизвестно
A6: 11 | B6: 0 | C6: 0 | D6: 0 | E6: 0 | F6: 0 | G6: 0 | H6: 0
A7: 12 | B7: 2 | C7: 2 | D7: 0 | E7: 0 | F7: 0 | G7: 0 | H7: 0
A8: 13 | B8: 31 | C8: 31 | D8: 0 | E8: 0 | F8: 0 | G8: 0 | H8: 0
A9: 14 | B9: 263 | C9: 259 | D9: 3 | E9: 0 | F9: 0 | G9: 0 | H9: 1
A10: 15 | B10: 1074 | C10: 1038 | D10: 32 | E10: 0 | F10: 0 | G10: 0 | H10: 4
A11: 16 | B11: 3807 | C11: 3609 | D11: 166 | E11: 11 | F11: 1 | G11: 0 | H11: 20
A12: 17 | B12: 10366 | C12: 9297 | D12: 777 | E12: 50 | F12: 1 | G12: 0 | H12: 241
A13: 18 | B13: 20928 | C13: 17543 | D13: 2266 | E13: 157 | F13: 12 | G13: 2 | H13: 948
A14: 19 | B14: 34181 | C14: 27290 | D14: 5020 | E14: 440 | F14: 19 | G14: 3 | H14: 1409
A15: 20 | B15: 45893 | C15: 33898 | D15: 9122 | E15: 1093 | F15: 111 | G15: 16 | H15: 1653
A16: 21 | B16: 57622 | C16: 39123 | D16: 14113 | E16: 2016 | F16: 244 | G16: 21 | H16: 2105
A17: 22 | B17: 66000 | C17: 42268 | D17: 17982 | E17: 3268 | F17: 429 | G17: 71 | H17: 1982
... A54: 59 | B54: 4 | C54: 1 | D54: 1 | E54: 1 | F54: 1 | G54: 0 | H54: 0
A55: 60 и старше | B55: 1 | C55: 1 | D55: 0 | E55: 0 | F55: 0 | G55: 0 | H55: 0
A56: не указан | B56: 913 | C56: 132 | D56: 115 | E56: 100 | F56: 55 | G56: 29 | H56: 482
A57: Итого | B57: 1888729 | C57: 735732 | D57: 762701 | E57: 255628 | F57: 66333 | G57: 33999 | H57: 34336

Sheet ТАБ_7
A1: 7. ЧИСЛО РОДИВШИХСЯ ЖИВЫМИ ПО ВОЗРАСТУ И ОБРАЗОВАНИЮ МАТЕРИ В 2016 ГОДУ
A3: Образование | B3: Всего | C3: в том числе:
C4: 14 и моложе | D4: 15-17 | E4: 18-19 | F4: 20-24 | G4: 25-29 | H4: 30-34 | I4: 35-39 | J4: 40-44 | K4: 45-49 | L4: 50-54 | M4: 55 и более | N4: неиз-вестно
A5: Всего | B5: 1888729 | C5: 296 | D5: 15247 | E5: 55109 | F5: 347203 | G5: 666445 | H5: 522258 | I5: 232158 | J5: 46623 | K5: 2265 | L5: 178 | M5: 34 | N5: 913
A6: в том числе:
A7: высшее профессиональное | B7: 866449 | C7: 0 | D7: 0 | E7: 31 | F7: 74033 | G7: 352382 | H7: 296533 | I7: 120528 | J7: 21710 | K7: 1109 | L7: 96 | M7: 18 | N7: 9
A8: неполное высшее профессиональное | B8: 69318 | C8: 0 | D8: 0 | E8: 395 | F8: 31674 | G8: 21188 | H8: 11489 | I8: 3903 | J8: 636 | K8: 31 | L8: 1 | M8: 0 | N8: 1
A9: среднее профессиональное | B9: 460466 | C9: 0 | D9: 1 | E9: 13606 | F9: 111676 | G9: 150307 | H9: 112735 | I9: 58241 | J9: 13265 | K9: 558 | L9: 28 | M9: 8 | N9: 41
A10: начальное профессиональное | B10: 13429 | C10: 15 | D10: 693 | E10: 1657 | F10: 3108 | G10: 3743 | H10: 2629 | I10: 1276 | J10: 293 | K10: 13 | L10: 0 | M10: 0 | N10: 2
A11: среднее (полное) общее | B11: 225431 | C11: 4 | D11: 3816 | E11: 18385 | F11: 60028 | G11: 65084 | H11: 48098 | I11: 24303 | J11: 5433 | K11: 205 | L11: 10 | M11: 4 | N11: 61
A12: основное общее | B12: 83570 | C12: 61 | D12: 7730 | E12: 11627 | F12: 21677 | G12: 19211 | H12: 14044 | I12: 7627 | J12: 1498 | K12: 43 | L12: 5 | M12: 0 | N12: 47
A13: начальное общее | B13: 10006 | C13: 157 | D13: 998 | E13: 884 | F13: 2209 | G13: 2514 | H13: 1932 | I13: 981 | J13: 226 | K13: 36 | L13: 9 | M13: 0 | N13: 60
A14: не имеющие начального общего | B14: 4476 | C14: 33 | D14: 332 | E14: 399 | F14: 1229 | G14: 1259 | H14: 782 | I14: 299 | J14: 111 | K14: 27 | L14: 1 | M14: 0 | N14: 4
A15: не указавшие | B15: 155584 | C15: 26 | D15: 1677 | E15: 8125 | F15: 41569 | G15: 50757 | H15: 34016 | I15: 15000 | J15: 3451 | K15: 243 | L15: 28 | M15: 4 | N15: 688

Sheet ТАБ_8
A1: 8. СМЕРТНОСТЬ НАСЕЛЕНИЯ ПО ОСНОВНЫМ КЛАССАМ И ОТДЕЛЬНЫМ ПРИЧИНАМ СМЕРТИ
B3: Число умерших | E3: Число умерших на 100000 человек населения
B5: 2016г. | C5: 2015г. | D5: в % к общему числу умерших в 2016г. | E5: 2016г. | F5: 2015г.
A6: Всего умерших от всех причин | B6: 1888729 | C6: 1908541 | D6: 100 | E6: 1289.259 | F6: 1303.6
A7: от болезней системы кровообращения | B7: 904055 | C7: 930102 | D7: 47.8 | E7: 616.4 | F7: 635.3
A8: из них от:
A9: ишемических болезней сердца | B9: 481780 | C9: 494638 | D9: 25.5 | E9: 328.5 | F9: 337.9
A10: цереброваскулярных болезней | B10: 279818 | C10: 290300 | D10: 14.8 | E10: 190.8 | F10: 198.3
A11: от новообразований | B11: 299652 | C11: 300232 | D11: 15.8 | E11: 204.3 | F11: 205.1
A12: из них от злокачественных | B12: 295729 | C12: 296476 | D12: 15.6 | E12: 201.6 | F12: 202.5
A13: от внешних причин смерти | B13: 167543 | C13: 177590 | D13: 8.9 | E13: 114.2 | F13: 121.3
A14: из них от:
A15: случайных отравлений алкоголем | B15: 14021 | C15: 15242 | D15: 0.7 | E15: 9.6 | F15: 10.4
A16: самоубийств | B16: 23119 | C16: 25476 | D16: 1.2 | E16: 15.8 | F16: 17.4
A17: убийств | B17: 10569 | C17: 11984 | D17: 0.6 | E17: 7.2 | F17: 8.2
A18: всех видов транспортных несчастных случаев: | B18: 21610 | C18: 24821 | D18: 1.1 | E18: 14.7 | F18: 17
A19: в том числе от ДТП | B19: 15854 | C19: 17919 | D19: 0.8 | E19: 10.8 | F19: 12.2
A20: от болезней органов дыхания | B20: 70332 | C20: 75813 | D20: 3.7 | E20: 48 | F20: 51.8
A21: от болезней органов пищеварения | B21: 98215 | C21: 101956 | D21: 5.2 | E21: 67 | F21: 69.6
A22: из них от язвенной болезни (всех форм) | B22: 10354 | C22: 10854 | D22: 0.5 | E22: 7.1 | F22: 7.4
A23: от некоторых инфекционных и паразитарных болезней | B23: 35335 | C23: 34372 | D23: 1.9 | E23: 24.1 | F23: 23.5
A24: из них от:
A25: кишечных инфекций | B25: 298 | C25: 335 | D25: 0.02 | E25: 0.2 | F25: 0.239
A26: туберкулеза (всех форм) | B26: 11373 | C26: 13484 | D26: 0.6 | E26: 7.8 | F26: 9.2
A27: от болезней мочеполовой системы | B27: 17928 | C27: 17078 | D27: 0.9 | E27: 12.2 | F27: 11.7
A28: от болезней нервной системы | B28: 83925 | C28: 59961 | D28: 4.4 | E28: 57.2 | F28: 41
A29: от болезней глаза и его придаточного аппарата | B29: 3 | C29: 5 | D29: 0.0002 | E29: 0.002 | F29: 0.003
A30: от болезней уха и сосцевидного отростка | B30: 176 | C30: 175 | D30: 0.01 | E30: 0.1 | F30: 0.1
A31: от болезней эндокринной системы, расстройства питания и нарушения обмена веществ | B31: 33711 | C31: 28365 | D31: 1.8 | E31: 23 | F31: 19.4
A32: из них от сахарного диабета | B32: 31502 | C32: 26773 | D32: 1.7 | E32: 21.5 | F32: 18.3
A33: от психических расстройств и расстройства поведения | B33: 15847 | C33: 14427 | D33: 0.8 | E33: 10.8 | F33: 9.9
A34: от болезней костно-мышечной системы и соединительной ткани | B34: 4483 | C34: 3584 | D34: 0.2 | E34: 3.1 | F34: 2.4
A35: от болезней крови, кроветворных органов и отдельных нарушений с вовлечением иммунного механизма | B35: 1637 | C35: 1684 | D35: 0.1 | E35: 1.1 | F35: 1.2
A36: из них от анемий | B36: 982 | C36: 1008 | D36: 0.1 | E36: 0.7 | F36: 0.7
... A38: от осложнений беременности, родов и послеродового периода | B38: 189 | C38: 197 | D38: 0.01 | E38: 0.1 | F38: 0.1
A39: из них от материнской смертности | B39: 188 | C39: 196 | D39: 0.01 | E39: 10,01) | F39: 10,11)
A40: от симптомов, признаков и отклонений от нормы,выявленных при клинических и лабораторных исследованиях, не классифицированных в других рубриках | B40: 144217 | C40: 149147 | D40: 7.6 | E40: 98.3 | F40: 101.9
A41: из них от:
A42: старости | B42: 108744 | C42: 105719 | D42: 5.8 | E42: 74.1 | F42: 72.2
A43: смерти по неустановленным причинам | B43: 34108 | C43: 42254 | D43: 1.8 | E43: 23.3 | F43: 28.8
...

Sheet ТАБ_9
A1: 9. УМЕРШИЕ ПО ОСНОВНЫМ КЛАССАМ ПРИЧИН СМЕРТИ ПО СУБЪЕКТАМ РОССИЙСКОЙ ФЕДЕРАЦИИ
A2: ЗА 2016 ГОД | C2: ЗА | D2: 1998 год
B4: Число умерших от :
B5: некоторых инфекционных и паразитарных болезней | C5: в том числе от туберкулеза | D5: новообразо-ваний | E5: болезней системы кровообраще-ния | F5: болезней органов дыхания | G5: болезней органов пищеварения | H5: внешних причин
A6: РОССИЙСКАЯ ФЕДЕРАЦИЯ | B6: 35335 | C6: 11373 | D6: 299652 | E6: 904055 | F6: 70332 | G6: 98215 | H6: 167543
A7: Центральный федеральный округ | B7: 4797 | C7: 1449 | D7: 85585 | E7: 256647 | F7: 19774 | G7: 26856 | H7: 39481
A8: Белгородская область | B8: 64 | C8: 10 | D8: 3080 | E8: 11765 | F8: 809 | G8: 784 | H8: 1295
A9: Брянская область | B9: 156 | C9: 89 | D9: 2954 | E9: 9139 | F9: 858 | G9: 1055 | H9: 1631
A10: Владимирская область | B10: 152 | C10: 60 | D10: 3482 | E10: 11517 | F10: 860 | G10: 1902 | H10: 1740
A11: Воронежская область | B11: 168 | C11: 85 | D11: 4328 | E11: 14049 | F11: 1164 | G11: 1445 | H11: 4086
A12: Ивановская область | B12: 200 | C12: 35 | D12: 2171 | E12: 6136 | F12: 575 | G12: 1071 | H12: 1161
A13: Калужская область | B13: 143 | C13: 52 | D13: 2334 | E13: 7947 | F13: 638 | G13: 768 | H13: 1215
A14: Костромская область | B14: 54 | C14: 13 | D14: 1578 | E14: 5320 | F14: 328 | G14: 504 | H14: 770
A15: Курская область | B15: 115 | C15: 88 | D15: 2713 | E15: 8516 | F15: 820 | G15: 938 | H15: 1133
A16: Липецкая область | B16: 61 | C16: 27 | D16: 2313 | E16: 7229 | F16: 714 | G16: 700 | H16: 1336
A17: Московская область | B17: 986 | C17: 261 | D17: 14569 | E17: 47120 | F17: 3761 | G17: 5604 | H17: 7994
... A101: Чукотский автономный округ | B101: 16 | C101: 11 | D101: 78 | E101: 203 | F101: 20 | G101: 35 | H101: 108

Sheet ТАБ_10
A1: 10. СМЕРТНОСТЬ НАСЕЛЕНИЯ ПО ОСНОВНЫМ КЛАССАМ ПРИЧИН СМЕРТИ ПО СУБЪЕКТАМ РОССИЙСКОЙ ФЕДЕРАЦИИ
A2: ЗА 2016 ГОД | C2: ЗА | D2: 1998 год
B4: Число умерших на 100000 человек населения от :
B5: некоторых инфекционных и паразитарных болезней | C5: в том числе от туберкулеза | D5: новообразо-ваний | E5: болезней системы кровообраще-ния | F5: болезней органов дыхания | G5: болезней органов пищеварения | H5: внешних причин
A6: РОССИЙСКАЯ ФЕДЕРАЦИЯ | B6: 24.091 | C6: 7.754 | D6: 204.297 | E6: 616.368 | F6: 47.951 | G6: 66.961 | H6: 114.228
A7: Центральный федеральный округ | B7: 12.251 | C7: 3.7 | D7: 218.569 | E7: 655.432 | F7: 50.499 | G7: 68.586 | H7: 100.828
A8: Белгородская область | B8: 4.125 | C8: 0.645 | D8: 198.517 | E8: 758.298 | F8: 52.143 | G8: 50.532 | H8: 83.468
A9: Брянская область | B9: 12.754 | C9: 7.276 | D9: 241.511 | E9: 747.178 | F9: 70.148 | G9: 86.254 | H9: 133.346
A10: Владимирская область | B10: 10.909 | C10: 4.306 | D10: 249.895 | E10: 826.549 | F10: 61.72 | G10: 136.502 | H10: 124.876
A11: Воронежская область | B11: 7.197 | C11: 3.641 | D11: 185.398 | E11: 601.814 | F11: 49.862 | G11: 61.899 | H11: 175.031
A12: Ивановская область | B12: 19.484 | C12: 3.41 | D12: 211.495 | E12: 597.757 | F12: 56.015 | G12: 104.335 | H12: 113.102
A13: Калужская область | B13: 14.128 | C13: 5.137 | D13: 230.593 | E13: 785.144 | F13: 63.033 | G13: 75.877 | H13: 120.039
A14: Костромская область | B14: 8.31 | C14: 2.001 | D14: 242.842 | E14: 818.708 | F14: 50.477 | G14: 77.562 | H14: 118.497
A15: Курская область | B15: 10.255 | C15: 7.847 | D15: 241.918 | E15: 759.37 | F15: 73.119 | G15: 83.641 | H15: 101.029
A16: Липецкая область | B16: 5.276 | C16: 2.335 | D16: 200.059 | E16: 625.261 | F16: 61.756 | G16: 60.545 | H16: 115.555
A17: Московская область | B17: 13.377 | C17: 3.541 | D17: 197.651 | E17: 639.257 | F17: 51.024 | G17: 76.027 | H17: 108.451
... A101: Чукотский автономный округ | B101: 32.006 | C101: 22.004 | D101: 156.031 | E101: 406.081 | F101: 40.008 | G101: 70.014 | H101: 216.043

Sheet ТАБ_11
A1: 11. ЧИСЛО УМЕРШИХ ОТ ВНЕШНИХ ПРИЧИН СМЕРТИ ПО СУБЪЕКТАМ РОССИЙСКОЙ ФЕДЕРАЦИИ
A2: ЗА 2016 ГОД
B4: Число умерших от :
B5: всех видов транспортных несчастных случаев | C5: случайных отравлений алкоголем | D5: случайных утоплений | E5: самоубийств | F5: убийств
A6: РОССИЙСКАЯ ФЕДЕРАЦИЯ | B6: 21610 | C6: 14021 | D6: 6517 | E6: 23119 | F6: 10569
A7: Центральный федеральный округ | B7: 5782 | C7: 4254 | D7: 1299 | E7: 4407 | F7: 2121
A8: Белгородская область | B8: 234 | C8: 80 | D8: 71 | E8: 247 | F8: 71
A9: Брянская область | B9: 185 | C9: 118 | D9: 82 | E9: 183 | F9: 67
A10: Владимирская область | B10: 308 | C10: 205 | D10: 79 | E10: 289 | F10: 136
A11: Воронежская область | B11: 432 | C11: 439 | D11: 114 | E11: 329 | F11: 77
A12: Ивановская область | B12: 112 | C12: 171 | D12: 42 | E12: 221 | F12: 83
A13: Калужская область | B13: 204 | C13: 163 | D13: 55 | E13: 150 | F13: 67
A14: Костромская область | B14: 60 | C14: 141 | D14: 40 | E14: 158 | F14: 25
A15: Курская область | B15: 205 | C15: 70 | D15: 34 | E15: 89 | F15: 53
A16: Липецкая область | B16: 211 | C16: 204 | D16: 17 | E16: 180 | F16: 58
A17: Московская область | B17: 1282 | C17: 933 | D17: 290 | E17: 988 | F17: 650
... A101: Чукотский автономный округ | B101: 3 | C101: 4 | D101: 14 | E101: 31 | F101: 11

Sheet ТАБ_12
A1: 12. СМЕРТНОСТЬ НАСЕЛЕНИЯ ОТ ВНЕШНИХ ПРИЧИН СМЕРТИ ПО СУБЪЕКТАМ РОССИЙСКОЙ ФЕДЕРАЦИИ
A2: ЗА 2016 ГОД
B4: Число умерших на 100000 человек населения от:
B5: всех видов транспортных несчастных случаев | C5: случайных отравлений алкоголем | D5: случайных утоплений | E5: самоубийств | F5: убийств
A6: РОССИЙСКАЯ ФЕДЕРАЦИЯ | B6: 14.733 | C6: 9.559 | D6: 4.443 | E6: 15.762 | F6: 7.206
A7: Центральный федеральный округ | B7: 14.766 | C7: 10.864 | D7: 3.317 | E7: 11.255 | F7: 5.417
A8: Белгородская область | B8: 15.082 | C8: 5.156 | D8: 4.576 | E8: 15.92 | F8: 4.576
A9: Брянская область | B9: 15.125 | C9: 9.647 | D9: 6.704 | E9: 14.962 | F9: 5.478
A10: Владимирская область | B10: 22.104 | C10: 14.712 | D10: 5.67 | E10: 20.741 | F10: 9.76
A11: Воронежская область | B11: 18.505 | C11: 18.805 | D11: 4.883 | E11: 14.093 | F11: 3.298
A12: Ивановская область | B12: 10.911 | C12: 16.658 | D12: 4.092 | E12: 21.529 | F12: 8.086
A13: Калужская область | B13: 20.155 | C13: 16.104 | D13: 5.434 | E13: 14.82 | F13: 6.619
A14: Костромская область | B14: 9.234 | C14: 21.699 | D14: 6.156 | E14: 24.315 | F14: 3.847
A15: Курская область | B15: 18.28 | C15: 6.242 | D15: 3.032 | E15: 7.936 | F15: 4.726
A16: Липецкая область | B16: 18.25 | C16: 17.645 | D16: 1.47 | E16: 15.569 | F16: 5.017
A17: Московская область | B17: 17.392 | C17: 12.658 | D17: 3.934 | E17: 13.404 | F17: 8.818
... A101: Чукотский автономный округ | B101: 6.001 | C101: 8.002 | D101: 28.006 | E101: 62.012 | F101: 22.004

Sheet ТАБ_13
A1: 13. УМЕРШИЕ ПО ВОЗРАСТНЫМ ГРУППАМ И ОСНОВНЫМ КЛАССАМ ПРИЧИН СМЕРТИ В 2016 ГОДУ
A3: Возраст | B3: Число умерших от :
B4: некоторых инфекционных и паразитарных болезней | C4: в том числе от туберкулеза | D4: новообразова-ний | E4: болезней системы кровообраще-ния | F4: болезней органов дыхания | G4: болезней органов пищеварения | H4: внешних причин
A5: до 1 года | B5: 433 | C5: 3 | D5: 105 | E5: 131 | F5: 534 | G5: 70 | H5: 618
A6: 0-27 дней | B6: 17 | C6: 0 | D6: 25 | E6: 18 | F6: 63 | G6: 1 | H6: 71
A7: 1 | B7: 101 | C7: 2 | D7: 76 | E7: 30 | F7: 110 | G7: 14 | H7: 341
A8: 2 | B8: 37 | C8: 2 | D8: 76 | E8: 15 | F8: 53 | G8: 10 | H8: 234
A9: 3 | B9: 38 | C9: 3 | D9: 88 | E9: 11 | F9: 38 | G9: 9 | H9: 183
A10: 4 | B10: 23 | C10: 0 | D10: 65 | E10: 4 | F10: 21 | G10: 13 | H10: 191
A11: 1-4 | B11: 199 | C11: 7 | D11: 305 | E11: 60 | F11: 222 | G11: 46 | H11: 949
A12: 5-9 | B12: 54 | C12: 1 | D12: 261 | E12: 47 | F12: 79 | G12: 25 | H12: 750
A13: 10-14 | B13: 31 | C13: 2 | D13: 223 | E13: 94 | F13: 76 | G13: 26 | H13: 1080
A14: 15-19 | B14: 65 | C14: 8 | D14: 254 | E14: 257 | F14: 101 | G14: 47 | H14: 2998
A15: 20-24 | B15: 415 | C15: 131 | D15: 422 | E15: 734 | F15: 189 | G15: 191 | H15: 6332
A16: 25-29 | B16: 2509 | C16: 552 | D16: 1105 | E16: 2504 | F16: 613 | G16: 1242 | H16: 11998
A17: 30-34 | B17: 5989 | C17: 1112 | D17: 2170 | E17: 5331 | F17: 1404 | G17: 3294 | H17: 16000
A18: 35-39 | B18: 7605 | C18: 1502 | D18: 3725 | E18: 9350 | F18: 2193 | G18: 5617 | H18: 17158
A19: 40-44 | B19: 5282 | C19: 1432 | D19: 6091 | E19: 14169 | F19: 2747 | G19: 6520 | H19: 16342
A20: 45-49 | B20: 3237 | C20: 1362 | D20: 10107 | E20: 19618 | F20: 2819 | G20: 6865 | H20: 14285
A21: 50-54 | B21: 2623 | C21: 1431 | D21: 19876 | E21: 34948 | F21: 4044 | G21: 8686 | H21: 16043
A22: 55-59 | B22: 2286 | C22: 1368 | D22: 36234 | E22: 59777 | F22: 6301 | G22: 11767 | H22: 17313
... A31: в т.ч. в трудоспособном возрасте | B31: 29427 | C31: 8678 | D31: 65891 | E31: 130845 | F31: 18996 | G31: 39653 | H31: 114441

Sheet ТАБ_14
A1: 14. МАТЕРИНСКАЯ СМЕРТНОСТЬ ПО СУБЪЕКТАМ РОССИЙСКОЙ ФЕДЕРАЦИИ
B3: 2016г. | C3: 2015г. | D3: на 100000 родившихся живыми
D4: 2016г. | E4: 2015г.
A5: РОССИЙСКАЯ ФЕДЕРАЦИЯ | B5: 188 | C5: 196 | D5: 10 | E5: 10.1
A6: Центральный федеральный округ | B6: 47 | C6: 47 | D6: 10.3 | E6: 10.3
A7: Белгородская область | B7: 2 | C7: 2 | D7: 11.6 | E7: 11.3
A8: Брянская область | B8: 1 | C8: 1 | D8: 7.5 | E8: 7.1
A9: Владимирская область | B9: 2 | C9: 3 | D9: 12.8 | E9: 18.5
A10: Воронежская область | B10: 1 | C10: 1 | D10: 4 | E10: 3.9
A11: Ивановская область | B11: 0 | C11: 1 | D11: 0 | E11: 8.5
A12: Калужская область | B12: 0 | C12: 0 | D12: 0 | E12: 0
A13: Костромская область | B13: 3 | C13: 2 | D13: 38.3 | E13: 24.5
A14: Курская область | B14: 0 | C14: 0 | D14: 0 | E14: 0
A15: Липецкая область | B15: 0 | C15: 1 | D15: 0 | E15: 7.5
A16: Московская область | B16: 4 | C16: 9 | D16: 4.1 | E16: 9.6
... A100: Чукотский автономный округ | B100: 0 | C100: 0 | D100: 0 | E100: 0

Sheet ТАБ_15
A1: 15. ПЕРИНАТАЛЬНАЯ СМЕРТНОСТЬ ПО СУБЪЕКТАМ РОССИЙСКОЙ ФЕДЕРАЦИИ ЗА 2016 ГОД
B3: человек | E3: на 1000 родившихся живыми и мертвыми | G3: на 1000 родившихся живыми
B4: всего | C4: мертво- рожденные | D4: умершие в возрасте до 7 дней | E4: всего | F4: мертво- рожденные | G4: умершие в возрасте до 7 дней
A5: РОССИЙСКАЯ ФЕДЕРАЦИЯ | B5: 14997 | C5: 10884 | D5: 4113 | E5: 7.89 | F5: 5.73 | G5: 2.18
A6: Центральный федеральный округ | B6: 3217 | C6: 2334 | D6: 883 | E6: 7.02 | F6: 5.09 | G6: 1.94
A7: Белгородская область | B7: 98 | C7: 73 | D7: 25 | E7: 5.66 | F7: 4.21 | G7: 1.45
A8: Брянская область | B8: 140 | C8: 102 | D8: 38 | E8: 10.4 | F8: 7.57 | G8: 2.84
A9: Владимирская область | B9: 153 | C9: 107 | D9: 46 | E9: 9.71 | F9: 6.79 | G9: 2.94
A10: Воронежская область | B10: 128 | C10: 84 | D10: 44 | E10: 5.12 | F10: 3.36 | G10: 1.76
A11: Ивановская область | B11: 80 | C11: 56 | D11: 24 | E11: 7.14 | F11: 5 | G11: 2.15
A12: Калужская область | B12: 115 | C12: 79 | D12: 36 | E12: 9.33 | F12: 6.41 | G12: 2.94
A13: Костромская область | B13: 71 | C13: 50 | D13: 21 | E13: 9.01 | F13: 6.35 | G13: 2.68
A14: Курская область | B14: 87 | C14: 68 | D14: 19 | E14: 6.98 | F14: 5.45 | G14: 1.53
A15: Липецкая область | B15: 137 | C15: 99 | D15: 38 | E15: 10.38 | F15: 7.5 | G15: 2.9
A16: Московская область | B16: 534 | C16: 382 | D16: 152 | E16: 5.5 | F16: 3.94 | G16: 1.57
... A100: Чукотский автономный округ | B100: 9 | C100: 5 | D100: 4 | E100: 13.16 | F100: 7.31 | G100: 5.89

Sheet ТАБ_16
A1: 16. МЛАДЕНЧЕСКАЯ СМЕРТНОСТЬ ПО СУБЪЕКТАМ РОССИЙСКОЙ ФЕДЕРАЦИИ
B3: Число детей, умерших в возрасте до 1 года | E3: Число детей, умерших в возрасте до 1 года, на 1000 родившихся живыми
B5: 2016г. | C5: 2015г. | D5: Прирост, снижение / - / | E5: 2016г. | F5: 2015г.
A6: РОССИЙСКАЯ ФЕДЕРАЦИЯ | B6: 11428 | C6: 12664 | D6: =B6-C6 -> -1236 | E6: 6.022 | F6: 6.5
A7: Центральный федеральный округ | B7: 2572 | C7: 2718 | D7: =B7-C7 -> -146 | E7: 5.64 | F7: 6
A8: Белгородская область | B8: 108 | C8: 110 | D8: =B8-C8 -> -2 | E8: 5.974 | F8: 6.2
A9: Брянская область | B9: 103 | C9: 111 | D9: =B9-C9 -> -8 | E9: 7.64 | F9: 7.9
A10: Владимирская область | B10: 100 | C10: 107 | D10: =B10-C10 -> -7 | E10: 6.366 | F10: 6.6
A11: Воронежская область | B11: 120 | C11: 126 | D11: =B11-C11 -> -6 | E11: 4.79 | F11: 4.9
A12: Ивановская область | B12: 66 | C12: 64 | D12: =B12-C12 -> 2 | E12: 5.87 | F12: 5.5
A13: Калужская область | B13: 87 | C13: 111 | D13: =B13-C13 -> -24 | E13: 7.071 | F13: 8.8
A14: Костромская область | B14: 59 | C14: 58 | D14: =B14-C14 -> 1 | E14: 7.496 | F14: 7.1
A15: Курская область | B15: 75 | C15: 61 | D15: =B15-C15 -> 14 | E15: 5.957 | F15: 4.7
A16: Липецкая область | B16: 96 | C16: 102 | D16: =B16-C16 -> -6 | E16: 7.291 | F16: 7.6
A17: Московская область | B17: 437 | C17: 452 | D17: =B17-C17 -> -15 | E17: 4.537 | F17: 4.8
... A101: Чукотский автономный округ | B101: 11 | C101: 11 | D101: =B101-C101 -> 0 | E101: 16.15 | F101: 16

Sheet ТАБ_17
A1: 17. МЛАДЕНЧЕСКАЯ СМЕРТНОСТЬ В РОССИЙСКОЙ ФЕДЕРАЦИИ ПО ОСНОВНЫМ КЛАССАМ И ОТДЕЛЬНЫМ ПРИЧИНАМ СМЕРТИ
B3: Число детей, умерших в возрасте до 1 года | E3: Число детей, умерших в возрасте до 1 года, на 10000 родившихся живыми
B5: 2016г. | C5: 2015г. | D5: в % к общему числу умерших в 2016г. | E5: 2016г. | F5: 2015г.
A6: Всего умерших от всех причин | B6: 11428 | C6: 12664 | D6: =ROUND(B6/$B$6*100,1) -> 100 | E6: 60.2 | F6: 65.2
A7: в том числе:
A8: от некоторых инфекционных и паразитарных болезней | B8: 433 | C8: 484 | D8: =ROUND(B8/$B$6*100,1) -> 3.8 | E8: 2.3 | F8: 2.5
A9: из них от:
A10: кишечных инфекций | B10: 73 | C10: 83 | D10: =ROUND(B10/$B$6*100,1) -> 0.6 | E10: 0.4 | F10: 0.4
A11: септицемии | B11: 88 | C11: 105 | D11: =ROUND(B11/$B$6*100,1) -> 0.8 | E11: 0.5 | F11: 0.5
A12: от болезней эндокринной системы, расстройства питания и нарушения обмена веществ | B12: 66 | C12: 65 | D12: =ROUND(B12/$B$6*100,1) -> 0.6 | E12: 0.3 | F12: 0.3
A13: от болезней нервной системы | B13: 387 | C13: 354 | D13: =ROUND(B13/$B$6*100,1) -> 3.4 | E13: 2 | F13: 1.8
A14: из них от менингита, за исключением менингита при инфекционных и паразитарных заболеваниях | B14: 55 | C14: 43 | D14: =ROUND(B14/$B$6*100,1) -> 0.5 | E14: 0.3 | F14: 0.2
A15: от болезней органов дыхания | B15: 534 | C15: 601 | D15: =ROUND(B15/$B$6*100,1) -> 4.7 | E15: 2.8 | F15: 3.1
A16: из них от:
A17: пневмоний | B17: 346 | C17: 401 | D17: =ROUND(B17/$B$6*100,1) -> 3 | E17: 1.8 | F17: 2.1
A18: гриппа и ОРЗ | B18: 134 | C18: 146 | D18: =ROUND(B18/$B$6*100,1) -> 1.2 | E18: 0.7 | F18: 0.7
A19: от болезней органов пищеварения | B19: 70 | C19: 86 | D19: =ROUND(B19/$B$6*100,1) -> 0.6 | E19: 0.4 | F19: 0.4
A20: от врожденных аномалий (пороков развития), деформаций и хромосомных нарушений | B20: 2550 | C20: 2707 | D20: =ROUND(B20/$B$6*100,1) -> 22.3 | E20: 13.4 | F20: 13.9
A21: из них от:
A22: врожденной гидроцефалии и spina bifida | B22: 73 | C22: 107 | D22: =ROUND(B22/$B$6*100,1) -> 0.6 | E22: 0.4 | F22: 0.6
A23: врожденных аномалий системы кровообращения | B23: 1118 | C23: 1235 | D23: =ROUND(B23/$B$6*100,1) -> 9.8 | E23: 5.9 | F23: 6.4
A24: от отдельных состояний, возникающих в перинатальном периоде | B24: 5942 | C24: 6718 | D24: =ROUND(B24/$B$6*100,1) -> 52 | E24: 31.3 | F24: 34.6
A25: из них от:
A26: родовых травм | B26: 91 | C26: 109 | D26: =ROUND(B26/$B$6*100,1) -> 0.8 | E26: 0.5 | F26: 0.6
A27: внутриутробной гипоксии и асфиксии в родах | B27: 456 | C27: 532 | D27: =ROUND(B27/$B$6*100,1) -> 4 | E27: 2.4 | F27: 2.7
A28: дыхательные расстройства новорожденного | B28: 827 | C28: 1057 | D28: =ROUND(B28/$B$6*100,1) -> 7.2 | E28: 4.4 | F28: 5.4
A29: от внешних причин смерти | B29: 618 | C29: 713 | D29: =ROUND(B29/$B$6*100,1) -> 5.4 | E29: 3.3 | F29: 3.7

Sheet ТАБ_18
A1: 18. УМЕРШИЕ В ВОЗРАСТЕ ДО 1 ГОДА ПО ОСНОВНЫМ КЛАССАМ ПРИЧИН СМЕРТИ
A2: ПО СУБЪЕКТАМ РОССИЙСКОЙ ФЕДЕРАЦИИ ЗА 2016 ГОД
B3: ЗА 1998 год | C3: за | D3: 1998 год
B4: Число детей, умерших в возрасте до 1 года от:
B5: отдельных состояний, возникающих в перинатальном периоде | C5: врожденных аномалий (пороков развития) | D5: болезней органов дыхания | E5: некоторых инфекционных и паразитарных болезней | F5: внешних причин | G5: болезней органов пищеварения
A6: РОССИЙСКАЯ ФЕДЕРАЦИЯ | B6: 5942 | C6: 2550 | D6: 534 | E6: 433 | F6: 618 | G6: 70
A7: Центральный федеральный округ | B7: 1338 | C7: 718 | D7: 85 | E7: 75 | F7: 87 | G7: 6
A8: Белгородская область | B8: 66 | C8: 19 | D8: 0 | E8: 4 | F8: 3 | G8: 0
A9: Брянская область | B9: 50 | C9: 26 | D9: 5 | E9: 3 | F9: 11 | G9: 0
A10: Владимирская область | B10: 62 | C10: 20 | D10: 1 | E10: 2 | F10: 6 | G10: 0
A11: Воронежская область | B11: 55 | C11: 32 | D11: 7 | E11: 9 | F11: 1 | G11: 0
A12: Ивановская область | B12: 27 | C12: 23 | D12: 2 | E12: 2 | F12: 3 | G12: 0
A13: Калужская область | B13: 48 | C13: 25 | D13: 2 | E13: 7 | F13: 3 | G13: 0
A14: Костромская область | B14: 33 | C14: 13 | D14: 6 | E14: 3 | F14: 1 | G14: 0
A15: Курская область | B15: 31 | C15: 20 | D15: 2 | E15: 1 | F15: 7 | G15: 0
A16: Липецкая область | B16: 63 | C16: 15 | D16: 1 | E16: 4 | F16: 3 | G16: 1
A17: Московская область | B17: 238 | C17: 117 | D17: 20 | E17: 12 | F17: 11 | G17: 1
... A101: Чукотский автономный округ | B101: 4 | C101: 2 | D101: 2 | E101: 1 | F101: 2 | G101: 0

Sheet ТАБ_19
A1: 19. КОЭФФИЦИЕНТЫ МЛАДЕНЧЕСКОЙ СМЕРТНОСТИ ПО ОСНОВНЫМ КЛАССАМ ПРИЧИН СМЕРТИ
A2: ПО СУБЪЕКТАМ РОССИЙСКОЙ ФЕДЕРАЦИИ ЗА 2016 ГОД
B3: за | C3: 1998 год
B4: Число детей, умерших в возрасте до 1 года, на 10000 родившихся живыми от:
B5: отдельных состояний, возникающих в перинатальном периоде | C5: врожденных аномалий(пороков развития) | D5: болезней органов дыхания | E5: некоторых инфекционных и паразитарных болезней | F5: внешних причин | G5: болезней органов пищеварения
A6: РОССИЙСКАЯ ФЕДЕРАЦИЯ | B6: 31.3 | C6: 13.4 | D6: 2.8 | E6: 2.3 | F6: 3.3 | G6: 0.4
A7: Центральный федеральный округ | B7: 29.3 | C7: 15.7 | D7: 1.9 | E7: 1.6 | F7: 1.9 | G7: 0.1
A8: Белгородская область | B8: 36.5 | C8: 10.5 | D8: 0 | E8: 2.2 | F8: 1.7 | G8: 0
A9: Брянская область | B9: 37.1 | C9: 19.3 | D9: 3.7 | E9: 2.2 | F9: 8.2 | G9: 0
A10: Владимирская область | B10: 39.5 | C10: 12.7 | D10: 0.6 | E10: 1.3 | F10: 3.8 | G10: 0
A11: Воронежская область | B11: 22 | C11: 12.8 | D11: 2.8 | E11: 3.6 | F11: 0.4 | G11: 0
A12: Ивановская область | B12: 24 | C12: 20.5 | D12: 1.8 | E12: 1.8 | F12: 2.7 | G12: 0
A13: Калужская область | B13: 39 | C13: 20.3 | D13: 1.6 | E13: 5.7 | F13: 2.4 | G13: 0
A14: Костромская область | B14: 41.9 | C14: 16.5 | D14: 7.6 | E14: 3.8 | F14: 1.3 | G14: 0
A15: Курская область | B15: 24.6 | C15: 15.9 | D15: 1.6 | E15: 0.8 | F15: 5.6 | G15: 0
A16: Липецкая область | B16: 47.8 | C16: 11.4 | D16: 0.8 | E16: 3 | F16: 2.3 | G16: 0.8
A17: Московская область | B17: 24.7 | C17: 12.1 | D17: 2.1 | E17: 1.2 | F17: 1.1 | G17: 0.1
... A101: Чукотский автономный округ | B101: 58.7 | C101: 29.4 | D101: 29.4 | E101: 14.7 | F101: 29.4 | G101: 0

Sheet ТАБ_20
A1: 20. ЧИСЛО БРАКОВ И РАЗВОДОВ ПО СУБЪЕКТАМ РОССИЙСКОЙ ФЕДЕРАЦИИ
B3: Число браков | D3: Прирост, снижение / - / | E3: Число разводов | G3: Прирост, снижение / - /
B4: 2016г. | C4: 2015г. | E4: 2016г. | F4: 2015г.
A5: РОССИЙСКАЯ ФЕДЕРАЦИЯ | B5: 985836 | C5: 1161068 | D5: =B5-C5 -> -175232 | E5: 608336 | F5: 611646 | G5: =E5-F5 -> -3310
A6: Центральный федеральный округ | B6: 263539 | C6: 313157 | D6: =B6-C6 -> -49618 | E6: 159704 | F6: 161463 | G6: =E6-F6 -> -1759
A7: Белгородская область | B7: 9522 | C7: 12859 | D7: =B7-C7 -> -3337 | E7: 6787 | F7: 6774 | G7: =E7-F7 -> 13
A8: Брянская область | B8: 7607 | C8: 9736 | D8: =B8-C8 -> -2129 | E8: 5804 | F8: 5883 | G8: =E8-F8 -> -79
A9: Владимирская область | B9: 8931 | C9: 10716 | D9: =B9-C9 -> -1785 | E9: 5592 | F9: 5861 | G9: =E9-F9 -> -269
A10: Воронежская область | B10: 14510 | C10: 18162 | D10: =B10-C10 -> -3652 | E10: 9617 | F10: 9666 | G10: =E10-F10 -> -49
A11: Ивановская область | B11: 6547 | C11: 7629 | D11: =B11-C11 -> -1082 | E11: 4217 | F11: 4255 | G11: =E11-F11 -> -38
A12: Калужская область | B12: 6958 | C12: 8322 | D12: =B12-C12 -> -1364 | E12: 4532 | F12: 4490 | G12: =E12-F12 -> 42
A13: Костромская область | B13: 4137 | C13: 5067 | D13: =B13-C13 -> -930 | E13: 2735 | F13: 2809 | G13: =E13-F13 -> -74
A14: Курская область | B14: 6836 | C14: 8949 | D14: =B14-C14 -> -2113 | E14: 4911 | F14: 5001 | G14: =E14-F14 -> -90
A15: Липецкая область | B15: 7209 | C15: 8732 | D15: =B15-C15 -> -1523 | E15: 4885 | F15: 4930 | G15: =E15-F15 -> -45
A16: Московская область | B16: 55034 | C16: 63451 | D16: =B16-C16 -> -8417 | E16: 33910 | F16: 33718 | G16: =E16-F16 -> 192
... A100: Чукотский автономный округ | B100: 356 | C100: 418 | D100: =B100-C100 -> -62 | E100: 261 | F100: 283 | G100: =E100-F100 -> -22

Sheet ТАБ_21
A1: 21. ОБЩИЕ КОЭФФИЦИЕНТЫ БРАЧНОСТИ И РАЗВОДИМОСТИ ПО СУБЪЕКТАМ РОССИЙСКОЙ ФЕДЕРАЦИИ
B3: На 1000 населения браков | D3: На 1000 населения разводов | F3: Число разводов на 1000 браков
B5: 2016г. | C5: 2015г. | D5: 2016г. | E5: 2015г. | F5: 2016г. | G5: 2015г.
A6: РОССИЙСКАЯ ФЕДЕРАЦИЯ | B6: 6.7 | C6: 7.9 | D6: 4.1 | E6: 4.2 | F6: =ROUND(ТАБ_20!E5/ТАБ_20!B5*1000,0) -> 617 | G6: =ROUND(ТАБ_20!F5/ТАБ_20!C5*1000,0) -> 527
A7: Центральный федеральный округ | B7: 6.7 | C7: 8 | D7: 4.1 | E7: 4.1 | F7: =ROUND(ТАБ_20!E6/ТАБ_20!B6*1000,0) -> 606 | G7: =ROUND(ТАБ_20!F6/ТАБ_20!C6*1000,0) -> 516
A8: Белгородская область | B8: 6.1 | C8: 8.3 | D8: 4.4 | E8: 4.4 | F8: =ROUND(ТАБ_20!E7/ТАБ_20!B7*1000,0) -> 713 | G8: =ROUND(ТАБ_20!F7/ТАБ_20!C7*1000,0) -> 527
A9: Брянская область | B9: 6.2 | C9: 7.9 | D9: 4.7 | E9: 4.8 | F9: =ROUND(ТАБ_20!E8/ТАБ_20!B8*1000,0) -> 763 | G9: =ROUND(ТАБ_20!F8/ТАБ_20!C8*1000,0) -> 604
A10: Владимирская область | B10: 6.4 | C10: 7.6 | D10: 4 | E10: 4.2 | F10: =ROUND(ТАБ_20!E9/ТАБ_20!B9*1000,0) -> 626 | G10: =ROUND(ТАБ_20!F9/ТАБ_20!C9*1000,0) -> 547
A11: Воронежская область | B11: 6.2 | C11: 7.8 | D11: 4.1 | E11: 4.1 | F11: =ROUND(ТАБ_20!E10/ТАБ_20!B10*1000,0) -> 663 | G11: =ROUND(ТАБ_20!F10/ТАБ_20!C10*1000,0) -> 532
A12: Ивановская область | B12: 6.4 | C12: 7.4 | D12: 4.1 | E12: 4.1 | F12: =ROUND(ТАБ_20!E11/ТАБ_20!B11*1000,0) -> 644 | G12: =ROUND(ТАБ_20!F11/ТАБ_20!C11*1000,0) -> 558
A13: Калужская область | B13: 6.9 | C13: 8.2 | D13: 4.5 | E13: 4.4 | F13: =ROUND(ТАБ_20!E12/ТАБ_20!B12*1000,0) -> 651 | G13: =ROUND(ТАБ_20!F12/ТАБ_20!C12*1000,0) -> 540
A14: Костромская область | B14: 6.4 | C14: 7.8 | D14: 4.2 | E14: 4.3 | F14: =ROUND(ТАБ_20!E13/ТАБ_20!B13*1000,0) -> 661 | G14: =ROUND(ТАБ_20!F13/ТАБ_20!C13*1000,0) -> 554
A15: Курская область | B15: 6.1 | C15: 8 | D15: 4.4 | E15: 4.5 | F15: =ROUND(ТАБ_20!E14/ТАБ_20!B14*1000,0) -> 718 | G15: =ROUND(ТАБ_20!F14/ТАБ_20!C14*1000,0) -> 559
A16: Липецкая область | B16: 6.2 | C16: 7.5 | D16: 4.2 | E16: 4.3 | F16: =ROUND(ТАБ_20!E15/ТАБ_20!B15*1000,0) -> 678 | G16: =ROUND(ТАБ_20!F15/ТАБ_20!C15*1000,0) -> 565
A17: Московская область | B17: 7.5 | C17: 8.7 | D17: 4.6 | E17: 4.6 | F17: =ROUND(ТАБ_20!E16/ТАБ_20!B16*1000,0) -> 616 | G17: =ROUND(ТАБ_20!F16/ТАБ_20!C16*1000,0) -> 531
... A38: г.Санкт-Петербург | B38: 9.6 | C38: 10.9 | D38: 4.8 | E38: 4.7 | F38: =ROUND(ТАБ_20!E37/ТАБ_20!B37*1000,0) -> 494 | G38: =ROUND(ТАБ_20!F37/ТАБ_20!C37*1000,0) -> 433
A39: Южный федеральный округ | B39: 6.7 | C39: 8.1 | D39: 4.2 | E39: 4.2 | F39: =ROUND(ТАБ_20!E38/ТАБ_20!B38*1000,0) -> 630 | G39: 522
A40: Республика Адыгея | B40: 5.3 | C40: 6.2 | D40: 3.6 | E40: 3.5 | F40: =ROUND(ТАБ_20!E39/ТАБ_20!B39*1000,0) -> 693 | G40: =ROUND(ТАБ_20!F39/ТАБ_20!C39*1000,0) -> 567
A41: Республика Калмыкия | B41: 5.1 | C41: 6.5 | D41: 3.8 | E41: 3.7 | F41: =ROUND(ТАБ_20!E40/ТАБ_20!B40*1000,0) -> 738 | G41: =ROUND(ТАБ_20!F40/ТАБ_20!C40*1000,0) -> 562
A42: Республика Крым | B42: 7.1 | C42: 9.2 | D42: 3.3 | E42: 3 | F42: =ROUND(ТАБ_20!E41/ТАБ_20!B41*1000,0) -> 465 | G42: =ROUND(ТАБ_20!F41/ТАБ_20!C41*1000,0) -> 326
A43: Краснодарский край | B43: 7.2 | C43: 8.4 | D43: 4.6 | E43: 4.6 | F43: =ROUND(ТАБ_20!E42/ТАБ_20!B42*1000,0) -> 634 | G43: =ROUND(ТАБ_20!F42/ТАБ_20!C42*1000,0) -> 550
A44: Астраханская область | B44: 6.6 | C44: 7.4 | D44: 4.2 | E44: 4.3 | F44: =ROUND(ТАБ_20!E43/ТАБ_20!B43*1000,0) -> 634 | G44: =ROUND(ТАБ_20!F43/ТАБ_20!C43*1000,0) -> 581
A45: Волгоградская область | B45: 6 | C45: 7 | D45: 4.1 | E45: 4.1 | F45: =ROUND(ТАБ_20!E44/ТАБ_20!B44*1000,0) -> 689 | G45: =ROUND(ТАБ_20!F44/ТАБ_20!C44*1000,0) -> 589
A46: Ростовская область | B46: 6.3 | C46: 7.8 | D46: 4.3 | E46: 4.3 | F46: =ROUND(ТАБ_20!E45/ТАБ_20!B45*1000,0) -> 684 | G46: =ROUND(ТАБ_20!F45/ТАБ_20!C45*1000,0) -> 556
A47: г.Севастополь | B47: 9.5 | C47: 11.5 | D47: 4.5 | E47: 4 | F47: =ROUND(ТАБ_20!E46/ТАБ_20!B46*1000,0) -> 472 | G47: =ROUND(ТАБ_20!F46/ТАБ_20!C46*1000,0) -> 349
A48: Северо-Кавказский федеральный округ | B48: 5.6 | C48: 6.2 | D48: 2.3 | E48: 2.3 | F48: =ROUND(ТАБ_20!E47/ТАБ_20!B47*1000,0) -> 419 | G48: =ROUND(ТАБ_20!F47/ТАБ_20!C47*1000,0) -> 379
A49: Республика Дагестан | B49: 5.8 | C49: 6.3 | D49: 1.6 | E49: 1.6 | F49: =ROUND(ТАБ_20!E48/ТАБ_20!B48*1000,0) -> 281 | G49: =ROUND(ТАБ_20!F48/ТАБ_20!C48*1000,0) -> 252
A50: Республика Ингушетия | B50: 3.8 | C50: 4.2 | D50: 0.9 | E50: 0.8 | F50: =ROUND(ТАБ_20!E49/ТАБ_20!B49*1000,0) -> 235 | G50: =ROUND(ТАБ_20!F49/ТАБ_20!C49*1000,0) -> 197
A51: Кабардино-Балкарская Республика | B51: 5.6 | C51: 6.2 | D51: 2.8 | E51: 2.5 | F51: =ROUND(ТАБ_20!E50/ТАБ_20!B50*1000,0) -> 495 | G51: =ROUND(ТАБ_20!F50/ТАБ_20!C50*1000,0) -> 403
... A101: Чукотский автономный округ | B101: 7.1 | C101: 8.3 | D101: 5.2 | E101: 5.6 | F101: =ROUND(ТАБ_20!E100/ТАБ_20!B100*1000,0) -> 733 | G101: =ROUND(ТАБ_20!F100/ТАБ_20!C100*1000,0) -> 677
A103: ОИПД ГМЦ РОССТАТА Зак.________________ Тир._____________2013г. | B103: ЗАМЕСТИТЕЛЬ РУКОВОДИТЕЛЯ ФЕДЕРАЛЬНОЙ
B104: СЛУЖБЫ ГОСУДАРСТВЕННОЙ СТАТИСТИКИ | F104: Г.К. ОКСЕНОЙТ
