Workbook

Sheet обложка
A3: ФЕДЕРАЛЬНАЯ СЛУЖБА ГОСУДАРСТВЕННОЙ СТАТИСТИКИ
B13: ЕСТЕСТВЕННОЕ ДВИЖЕНИЕ НАСЕЛЕНИЯ
B15: РОССИЙСКОЙ ФЕДЕРАЦИИ
B17: за 2019 год
B21: (Статистический бюллетень)
B31: МОСКВА 2020 г.

Sheet титул
A3: ФЕДЕРАЛЬНАЯ СЛУЖБА ГОСУДАРСТВЕННОЙ СТАТИСТИКИ
B13: ЕСТЕСТВЕННОЕ ДВИЖЕНИЕ НАСЕЛЕНИЯ
B15: РОССИЙСКОЙ ФЕДЕРАЦИИ
B17: за 2019 год
B21: (Статистический бюллетень)
B31: МОСКВА 2020 г.

Sheet содержание
B2: № табл. | C2: СОДЕРЖАНИЕ | D2: стр.
C4: Предисловие…………………………………………………………………………………………………………...………………………………..……………………………….. | D4: 3
B5: 1 | C5: Общие итоги естественного движения населения в Российской Федерации……………………………………….……………………………………… | D5: 5
B6: 2 | C6: Родившиеся, умершие и естественный прирост населения по субъектам Российской Федерации………………………………...…………………… | D6: 6
B7: 3 | C7: Общие коэффициенты рождаемости, смертности, естественного прироста населения по субъектам Российской Федерации……………..… | D7: 9
B8: 4 | C8: Родившиеся живыми у женщин, не состоявших в зарегистрированном браке, по субъектам Российской Федерации……………….…… | D8: 12
B9: 5 | C9: Родившиеся вне брака по возрасту матери по субъектам Российской Федерации в 2019 году……………………………………………………….…….. | D9: 15
B10: 6 | C10: Число родившихся живыми по возрасту матери и очередности рождения в Российской Федерации в 2019 году……………………………...……… | D10: 18
B11: 7 | C11: Число родившихся живыми по возрасту и образованию матери в 2019 году…………………………………………………………………………..………. | D11: 19
B12: 8 | C12: Смертность населения по основным классам и отдельным причинам смерти……………………………………………………………………..…...….. | D12: 20
B13: 9 | C13: Умершие по основным классам причин смерти по субъектам Российской Федерации…………………………………………………….……………. | D13: 22
B14: 10 | C14: Cмертность населения по основным классам причин смерти по субъектам Российской Федерации………………………………………..…………….. | D14: 25
B15: 11 | C15: Число умерших от внешних причин смерти по субъектам Российской Федерации……………………………………………………………...…………… | D15: 28
B16: 12 | C16: Смертность населения от внешних причин смерти по субъектам Российской Федерации…………………………………………………………..……………. | D16: 31
... B25: 21 | C25: Общие коэффициенты брачности и разводимости по субъектам Российской Федерации………………………………………………………….……. | D25: 54

Sheet предисловие

Sheet ТАБ_1 
A1: 1. ОБЩИЕ ИТОГИ ЕСТЕСТВЕННОГО ДВИЖЕНИЯ НАСЕЛЕНИЯ
A2: В РОССИЙСКОЙ ФЕДЕРАЦИИ
B4: Абсолютные данные | E4: На 1000 человек населения
B5: 2019 г. | C5: 2018 г. | D5: Прирост, снижение / - / | E5: 2019 г. | F5: 2018 г.
A6: Родившихся | B6: 1481074 | C6: 1604344 | D6: =B6-C6 -> -123270 | E6: 10.1 | F6: 10.9
A7: Умерших | B7: 1798307 | C7: 1828910 | D7: =B7-C7 -> -30603 | E7: 12.3 | F7: 12.5
A8: из них детей в возрасте до 1 года | B8: 7328 | C8: 8244 | D8: =B8-C8 -> -916 | E8: 4,91) | F8: 5,11)
A9: Естественный прирост, (убыль) | B9: -317233 | C9: -224566 | D9: Х | E9: -2.2 | F9: -1.6
A10: Браков | B10: 950167 | C10: 893039 | D10: =B10-C10 -> 57128 | E10: 6.5 | F10: 6.1
A11: Разводов | B11: 620730 | C11: 583942 | D11: =B11-C11 -> 36788 | E11: 4.2 | F11: 4
A13: 1) Рассчитывается на 1000 родившихся живыми.

Sheet ТАБ_2
A1: 2. РОДИВШИЕСЯ, УМЕРШИЕ И ЕСТЕСТВЕННЫЙ ПРИРОСТ НАСЕЛЕНИЯ ПО СУБЪЕКТАМ РОССИЙСКОЙ ФЕДЕРАЦИИ
B3: Число родившихся | D3: Прирост, снижение /-/ | E3: Число умерших | G3: Прирост, снижение /-/ | H3: Естественный прирост, убыль (-)
B5: 2019 г. | C5: 2018 г. | E5: 2019 г. | F5: 2018 г. | H5: 2019 г. | I5: 2018 г.
A6: РОССИЙСКАЯ ФЕДЕРАЦИЯ | B6: 1481074 | C6: 1604344 | D6: =B6-C6 -> -123270 | E6: 1798307 | F6: 1828910 | G6: =E6-F6 -> -30603 | H6: =B6-E6 -> -317233 | I6: -224566
A7: Центральный федеральный округ | B7: 366668 | C7: 391129 | D7: =B7-C7 -> -24461 | E7: 496740 | F7: 508436 | G7: =E7-F7 -> -11696 | H7: =B7-E7 -> -130072 | I7: -117307
A8: Белгородская область | B8: 13183 | C8: 14317 | D8: =B8-C8 -> -1134 | E8: 20662 | F8: 20898 | G8: =E8-F8 -> -236 | H8: =B8-E8 -> -7479 | I8: -6581
A9: Брянская область | B9: 9956 | C9: 11129 | D9: =B9-C9 -> -1173 | E9: 17615 | F9: 18273 | G9: =E9-F9 -> -658 | H9: =B9-E9 -> -7659 | I9: -7144
A10: Владимирская область | B10: 11101 | C10: 12693 | D10: =B10-C10 -> -1592 | E10: 21183 | F10: 21966 | G10: =E10-F10 -> -783 | H10: =B10-E10 -> -10082 | I10: -9273
A11: Воронежская область | B11: 19576 | C11: 21470 | D11: =B11-C11 -> -1894 | E11: 32882 | F11: 34280 | G11: =E11-F11 -> -1398 | H11: =B11-E11 -> -13306 | I11: -12810
A12: Ивановская область | B12: 7938 | C12: 9117 | D12: =B12-C12 -> -1179 | E12: 15799 | F12: 16226 | G12: =E12-F12 -> -427 | H12: =B12-E12 -> -7861 | I12: -7109
A13: Калужская область | B13: 8924 | C13: 10355 | D13: =B13-C13 -> -1431 | E13: 14656 | F13: 15067 | G13: =E13-F13 -> -411 | H13: =B13-E13 -> -5732 | I13: -4712
A14: Костромская область | B14: 5761 | C14: 6230 | D14: =B14-C14 -> -469 | E14: 9337 | F14: 9510 | G14: =E14-F14 -> -173 | H14: =B14-E14 -> -3576 | I14: -3280
A15: Курская область | B15: 9246 | C15: 10256 | D15: =B15-C15 -> -1010 | E15: 16562 | F15: 17156 | G15: =E15-F15 -> -594 | H15: =B15-E15 -> -7316 | I15: -6900
A16: Липецкая область | B16: 9788 | C16: 10884 | D16: =B16-C16 -> -1096 | E16: 16291 | F16: 16641 | G16: =E16-F16 -> -350 | H16: =B16-E16 -> -6503 | I16: -5757
A17: Московская область | B17: 72466 | C17: 83088 | D17: =B17-C17 -> -10622 | E17: 91448 | F17: 92305 | G17: =E17-F17 -> -857 | H17: =B17-E17 -> -18982 | I17: -9217
... A101: Чукотский автономный округ | B101: 525 | C101: 625 | D101: =B101-C101 -> -100 | E101: 454 | F101: 547 | G101: =E101-F101 -> -93 | H101: =B101-E101 -> 71 | I101: 78

Sheet ТАБ_3
A1: 3. ОБЩИЕ КОЭФФИЦИЕНТЫ РОЖДАЕМОСТИ, СМЕРТНОСТИ, ЕСТЕСТВЕННОГО ПРИРОСТА НАСЕЛЕНИЯ
A2: ПО СУБЪЕКТАМ РОССИЙСКОЙ ФЕДЕРАЦИИ
A3: ( на 1000 человек населения )
B4: Число родившихся | D4: Число умерших | F4: Естественный прирост, убыль ( - )
B6: 2019 г. | C6: 2018 г. | D6: 2019 г. | E6: 2018 г. | F6: 2019 г. | G6: 2018 г.
A7: РОССИЙСКАЯ ФЕДЕРАЦИЯ | B7: 10.1 | C7: 10.9 | D7: 12.3 | E7: 12.5 | F7: =B7-D7 -> -2.2 | G7: -1.6
A8: Центральный федеральный округ | B8: 9.3 | C8: 9.9 | D8: 12.6 | E8: 12.9 | F8: =B8-D8 -> -3.3 | G8: -3
A9: Белгородская область | B9: 8.5 | C9: 9.2 | D9: 13.3 | E9: 13.5 | F9: =B9-D9 -> -4.8 | G9: -4.3
A10: Брянская область | B10: 8.3 | C10: 9.2 | D10: 14.7 | E10: 15.2 | F10: =B10-D10 -> -6.4 | G10: -6
A11: Владимирская область | B11: 8.1 | C11: 9.3 | D11: 15.6 | E11: 16 | F11: =B11-D11 -> -7.5 | G11: -6.7
A12: Воронежская область | B12: 8.4 | C12: 9.2 | D12: 14.1 | E12: 14.7 | F12: =B12-D12 -> -5.7 | G12: -5.5
A13: Ивановская область | B13: 7.9 | C13: 9 | D13: 15.8 | E13: 16.1 | F13: =B13-D13 -> -7.9 | G13: -7.1
A14: Калужская область | B14: 8.9 | C14: 10.2 | D14: 14.6 | E14: 14.9 | F14: =B14-D14 -> -5.7 | G14: -4.7
A15: Костромская область | B15: 9.1 | C15: 9.7 | D15: 14.7 | E15: 14.9 | F15: =B15-D15 -> -5.6 | G15: -5.2
A16: Курская область | B16: 8.4 | C16: 9.2 | D16: 15 | E16: 15.4 | F16: =B16-D16 -> -6.6 | G16: -6.2
A17: Липецкая область | B17: 8.6 | C17: 9.5 | D17: 14.3 | E17: 14.5 | F17: =B17-D17 -> -5.7 | G17: -5
A18: Московская область | B18: 9.5 | C18: 11 | D18: 12 | E18: 12.2 | F18: =B18-D18 -> -2.5 | G18: -1.2
... A102: Чукотский автономный округ | B102: 10.5 | C102: 12.6 | D102: 9.1 | E102: 11 | F102: =B102-D102 -> 1.4 | G102: 1.6

Sheet ТАБ_4
A1: 4. РОДИВШИЕСЯ ЖИВЫМИ У ЖЕНЩИН, НЕ СОСТОЯВШИХ В ЗАРЕГИСТРИРОВАННОМ БРАКЕ,
A2: ПО СУБЪЕКТАМ РОССИЙСКОЙ ФЕДЕРАЦИИ
B4: 2019 г. | D4: 2018 г.
B5: всего родившихся у женщин вне брака | C5: % к общему числу родившихся | D5: всего родившихся у женщин вне брака | E5: % к общему числу родившихся
A6: РОССИЙСКАЯ ФЕДЕРАЦИЯ | B6: 309230 | C6: =ROUND(ТАБ_4!B6/ТАБ_2!B6*100,1) -> 20.9 | D6: 340364 | E6: =ROUND(D6/ТАБ_2!C6*100,1) -> 21.2
A7: Центральный федеральный округ | B7: 66535 | C7: =ROUND(ТАБ_4!B7/ТАБ_2!B7*100,1) -> 18.1 | D7: 72337 | E7: =ROUND(D7/ТАБ_2!C7*100,1) -> 18.5
A8: Белгородская область | B8: 1802 | C8: =ROUND(ТАБ_4!B8/ТАБ_2!B8*100,1) -> 13.7 | D8: 1909 | E8: =ROUND(D8/ТАБ_2!C8*100,1) -> 13.3
A9: Брянская область | B9: 1691 | C9: =ROUND(ТАБ_4!B9/ТАБ_2!B9*100,1) -> 17 | D9: 1975 | E9: =ROUND(D9/ТАБ_2!C9*100,1) -> 17.7
A10: Владимирская область | B10: 2175 | C10: =ROUND(ТАБ_4!B10/ТАБ_2!B10*100,1) -> 19.6 | D10: 2486 | E10: =ROUND(D10/ТАБ_2!C10*100,1) -> 19.6
A11: Воронежская область | B11: 3144 | C11: =ROUND(ТАБ_4!B11/ТАБ_2!B11*100,1) -> 16.1 | D11: 3353 | E11: =ROUND(D11/ТАБ_2!C11*100,1) -> 15.6
A12: Ивановская область | B12: 1691 | C12: =ROUND(ТАБ_4!B12/ТАБ_2!B12*100,1) -> 21.3 | D12: 1910 | E12: =ROUND(D12/ТАБ_2!C12*100,1) -> 20.9
A13: Калужская область | B13: 1821 | C13: =ROUND(ТАБ_4!B13/ТАБ_2!B13*100,1) -> 20.4 | D13: 2048 | E13: =ROUND(D13/ТАБ_2!C13*100,1) -> 19.8
A14: Костромская область | B14: 1079 | C14: =ROUND(ТАБ_4!B14/ТАБ_2!B14*100,1) -> 18.7 | D14: 1108 | E14: =ROUND(D14/ТАБ_2!C14*100,1) -> 17.8
A15: Курская область | B15: 1655 | C15: =ROUND(ТАБ_4!B15/ТАБ_2!B15*100,1) -> 17.9 | D15: 1818 | E15: =ROUND(D15/ТАБ_2!C15*100,1) -> 17.7
A16: Липецкая область | B16: 1614 | C16: =ROUND(ТАБ_4!B16/ТАБ_2!B16*100,1) -> 16.5 | D16: 1832 | E16: =ROUND(D16/ТАБ_2!C16*100,1) -> 16.8
A17: Московская область | B17: 13508 | C17: =ROUND(ТАБ_4!B17/ТАБ_2!B17*100,1) -> 18.6 | D17: 16044 | E17: =ROUND(D17/ТАБ_2!C17*100,1) -> 19.3
... A101: Чукотский автономный округ | B101: 222 | C101: =ROUND(ТАБ_4!B101/ТАБ_2!B101*100,1) -> 42.3 | D101: 253 | E101: =ROUND(D101/ТАБ_2!C101*100,1) -> 40.5

Sheet ТАБ_5
A1: 5. РОДИВШИЕСЯ ВНЕ БРАКА ПО ВОЗРАСТУ МАТЕРИ
A2: ПО СУБЪЕКТАМ РОССИЙСКОЙ ФЕДЕРАЦИИ ЗА 2019 ГОД
B4: 14 и моложе | C4: 15-19 | D4: 20-24 | E4: 25-29 | F4: 30-34 | G4: 35-39 | H4: 40-44 | I4: 45-49 | J4: 50-54 | K4: 55 и более | L4: неиз-вестно
A5: РОССИЙСКАЯ ФЕДЕРАЦИЯ | B5: 206 | C5: 24676 | D5: 61194 | E5: 71121 | F5: 82383 | G5: 54215 | H5: 14079 | I5: 894 | J5: 87 | K5: 17 | L5: 358
A6: Центральный федеральный округ | B6: 49 | C6: 3810 | D6: 11444 | E6: 15212 | F6: 18882 | G6: 13117 | H6: 3576 | I6: 290 | J6: 43 | K6: 6 | L6: 106
A7: Белгородская область | B7: 2 | C7: 148 | D7: 326 | E7: 412 | F7: 494 | G7: 337 | H7: 81 | I7: 1 | J7: 0 | K7: 0 | L7: 1
A8: Брянская область | B8: 5 | C8: 142 | D8: 332 | E8: 389 | F8: 432 | G8: 307 | H8: 77 | I8: 4 | J8: 0 | K8: 0 | L8: 3
A9: Владимирская область | B9: 2 | C9: 203 | D9: 386 | E9: 503 | F9: 593 | G9: 397 | H9: 85 | I9: 3 | J9: 0 | K9: 0 | L9: 3
A10: Воронежская область | B10: 3 | C10: 266 | D10: 607 | E10: 743 | F10: 831 | G10: 560 | H10: 124 | I10: 6 | J10: 0 | K10: 0 | L10: 4
A11: Ивановская область | B11: 3 | C11: 123 | D11: 296 | E11: 408 | F11: 460 | G11: 303 | H11: 92 | I11: 3 | J11: 0 | K11: 0 | L11: 3
A12: Калужская область | B12: 5 | C12: 142 | D12: 354 | E12: 431 | F12: 498 | G12: 309 | H12: 79 | I12: 1 | J12: 2 | K12: 0 | L12: 0
A13: Костромская область | B13: 0 | C13: 78 | D13: 191 | E13: 247 | F13: 317 | G13: 197 | H13: 42 | I13: 5 | J13: 0 | K13: 0 | L13: 2
A14: Курская область | B14: 1 | C14: 159 | D14: 377 | E14: 380 | F14: 409 | G14: 269 | H14: 57 | I14: 2 | J14: 1 | K14: 0 | L14: 0
A15: Липецкая область | B15: 3 | C15: 137 | D15: 290 | E15: 347 | F15: 469 | G15: 304 | H15: 61 | I15: 2 | J15: 1 | K15: 0 | L15: 0
A16: Московская область | B16: 6 | C16: 767 | D16: 2465 | E16: 3073 | F16: 3772 | G16: 2605 | H16: 726 | I16: 45 | J16: 6 | K16: 1 | L16: 42
... A100: Чукотский автономный округ | B100: 1 | C100: 40 | D100: 50 | E100: 51 | F100: 48 | G100: 21 | H100: 11 | I100: 0 | J100: 0 | K100: 0 | L100: 0

Sheet ТАБ_6
A1: 6. ЧИСЛО РОДИВШИХСЯ ЖИВЫМИ ПО ВОЗРАСТУ МАТЕРИ И ОЧЕРЕДНОСТИ РОЖДЕНИЯ
A2: В РОССИЙСКОЙ ФЕДЕРАЦИИ В 2019 ГОДУ
A4: Возраст матери (лет) | B4: Всего родившихся живыми | C4: в том числе по очередности рождения ребенка:
C5: первый | D5: второй | E5: третий | F5: четвертый | G5: пятый и более | H5: неизвестно
A6: 11 | B6: 0 | C6: 0 | D6: 0 | E6: 0 | F6: 0 | G6: 0 | H6: 0
A7: 12 | B7: 3 | C7: 3 | D7: 0 | E7: 0 | F7: 0 | G7: 0 | H7: 0
A8: 13 | B8: 24 | C8: 24 | D8: 0 | E8: 0 | F8: 0 | G8: 0 | H8: 0
A9: 14 | B9: 189 | C9: 188 | D9: 1 | E9: 0 | F9: 0 | G9: 0 | H9: 0
A10: 15 | B10: 927 | C10: 906 | D10: 19 | E10: 1 | F10: 0 | G10: 0 | H10: 1
A11: 16 | B11: 3036 | C11: 2879 | D11: 154 | E11: 2 | F11: 0 | G11: 0 | H11: 1
A12: 17 | B12: 7068 | C12: 6508 | D12: 508 | E12: 42 | F12: 2 | G12: 1 | H12: 7
A13: 18 | B13: 14381 | C13: 12756 | D13: 1488 | E13: 117 | F13: 17 | G13: 1 | H13: 2
A14: 19 | B14: 25018 | C14: 20755 | D14: 3797 | E14: 421 | F14: 29 | G14: 7 | H14: 9
A15: 20 | B15: 35107 | C15: 26437 | D15: 7481 | E15: 1030 | F15: 128 | G15: 26 | H15: 5
A16: 21 | B16: 43295 | C16: 29964 | D16: 11075 | E16: 1922 | F16: 285 | G16: 41 | H16: 8
A17: 22 | B17: 50661 | C17: 32657 | D17: 14167 | E17: 3163 | F17: 567 | G17: 98 | H17: 9
... A54: 59 | B54: 7 | C54: 1 | D54: 0 | E54: 2 | F54: 2 | G54: 2 | H54: 0
A55: 60 и старше | B55: 19 | C55: 5 | D55: 5 | E55: 6 | F55: 3 | G55: 0 | H55: 0
A56: не указан | B56: 818 | C56: 270 | D56: 191 | E56: 156 | F56: 86 | G56: 71 | H56: 44
A57: Итого | B57: 1481074 | C57: 557207 | D57: 549993 | E57: 253093 | F57: 77324 | G57: 42948 | H57: 509

Sheet ТАБ_7
A1: 7. ЧИСЛО РОДИВШИХСЯ ЖИВЫМИ ПО ВОЗРАСТУ И ОБРАЗОВАНИЮ МАТЕРИ В 2019 ГОДУ
A3: Образование | B3: Всего | C3: в том числе:
C4: 14 и моложе | D4: 15-17 | E4: 18-19 | F4: 20-24 | G4: 25-29 | H4: 30-34 | I4: 35-39 | J4: 40-44 | K4: 45-49 | L4: 50-54 | M4: 55 и более | N4: неиз-вестно
A5: Всего | B5: 1481074 | C5: 216 | D5: 11031 | E5: 39399 | F5: 256769 | G5: 437792 | H5: 451084 | I5: 231890 | J5: 49116 | K5: 2644 | L5: 237 | M5: 78 | N5: 818
A6: в том числе:
A7: высшее профессиональное | B7: 703025 | C7: 0 | D7: 0 | E7: 311 | F7: 52931 | G7: 228662 | H7: 262599 | I7: 131113 | J7: 25735 | K7: 1430 | L7: 126 | M7: 44 | N7: 74
A8: неполное высшее профессиональное | B8: 42008 | C8: 0 | D8: 0 | E8: 379 | F8: 17348 | G8: 11452 | H8: 8654 | I8: 3513 | J8: 615 | K8: 31 | L8: 6 | M8: 3 | N8: 7
A9: среднее профессиональное | B9: 366884 | C9: 0 | D9: 0 | E9: 8842 | F9: 89721 | G9: 105034 | H9: 97125 | I9: 53082 | J9: 12387 | K9: 600 | L9: 35 | M9: 11 | N9: 47
A10: начальное профессиональное | B10: 7046 | C10: 10 | D10: 359 | E10: 730 | F10: 1815 | G10: 1599 | H10: 1557 | I10: 804 | J10: 162 | K10: 8 | L10: 0 | M10: 0 | N10: 2
A11: среднее (полное) общее | B11: 214943 | C11: 2 | D11: 2528 | E11: 14812 | F11: 56922 | G11: 56166 | H11: 50728 | I11: 27089 | J11: 6342 | K11: 282 | L11: 27 | M11: 14 | N11: 31
A12: основное общее | B12: 80123 | C12: 44 | D12: 6236 | E12: 10499 | F12: 22267 | G12: 16561 | H12: 14455 | I12: 8145 | J12: 1838 | K12: 64 | L12: 3 | M12: 1 | N12: 10
A13: начальное общее | B13: 9090 | C13: 126 | D13: 943 | E13: 970 | F13: 2288 | G13: 1899 | H13: 1727 | I13: 902 | J13: 221 | K13: 8 | L13: 4 | M13: 0 | N13: 2
A14: не имеющие начального общего | B14: 5011 | C14: 22 | D14: 357 | E14: 469 | F14: 1372 | G14: 1335 | H14: 903 | I14: 428 | J14: 102 | K14: 23 | L14: 0 | M14: 0 | N14: 0
A15: не указавшие | B15: 52944 | C15: 12 | D15: 608 | E15: 2387 | F15: 12105 | G15: 15084 | H15: 13336 | I15: 6814 | J15: 1714 | K15: 198 | L15: 36 | M15: 5 | N15: 645

Sheet ТАБ_8
A1: 8. СМЕРТНОСТЬ НАСЕЛЕНИЯ ПО ОСНОВНЫМ КЛАССАМ И ОТДЕЛЬНЫМ ПРИЧИНАМ СМЕРТИ
B3: Число умерших | E3: Число умерших на 100000 человек населения
B5: 2019 г. | C5: 2018 г. | D5: в % к общему числу умерших в 2019 г. | E5: 2019 г. | F5: 2018 г.
A6: Всего умерших от всех причин | B6: 1798307 | C6: 1828910 | D6: =ROUND(B6/$B$6*100,1) -> 100 | E6: 1225.3 | F6: 1245.6
A7: от болезней системы кровообращения | B7: 841207 | C7: 856127 | D7: =ROUND(B7/$B$6*100,1) -> 46.8 | E7: 573.167 | F7: 582.9
A8: из них от:
A9: ишемических болезней сердца | B9: 442328 | C9: 453306 | D9: =ROUND(B9/$B$6*100,1) -> 24.6 | E9: 301.386 | F9: 308.7
A10: цереброваскулярных болезней | B10: 260594 | C10: 263573 | D10: =ROUND(B10/$B$6*100,1) -> 14.5 | E10: 177.559 | F10: 179.5
A11: острых нарушений мозгового кровообращения | B11: 129469 | C11: . . . | D11: =ROUND(B11/$B$6*100,1) -> 7.2 | E11: 88.215 | F11: . . .
A12: от новообразований | B12: 298699 | C12: 297996 | D12: =ROUND(B12/$B$6*100,1) -> 16.6 | E12: 203.522 | F12: 203
A13: из них от злокачественных | B13: 294400 | C13: 293704 | D13: =ROUND(B13/$B$6*100,1) -> 16.4 | E13: 200.593 | F13: 200
A14: от внешних причин смерти | B14: 137633 | C14: 144612 | D14: =ROUND(B14/$B$6*100,1) -> 7.7 | E14: 93.778 | F14: 98.6
A15: из них от:
A16: причин смерти, обусловленных алкоголем | B16: 47427 | C16: 48786 | D16: =ROUND(B16/$B$6*100,1) -> 2.6 | E16: 32.315 | F16: 33.2
A17: самоубийств | B17: 17192 | C17: 18206 | D17: =ROUND(B17/$B$6*100,1) -> 1 | E17: 11.714 | F17: 12.4
A18: убийств | B18: 7302 | C18: 7986 | D18: =ROUND(B18/$B$6*100,1) -> 0.4 | E18: 4.975 | F18: 5.4
A19: всех видов транспортных несчастных случаев: | B19: 17787 | C19: 19092 | D19: =ROUND(B19/$B$6*100,1) -> 1 | E19: 12.119 | F19: 13
A20: в том числе от ДТП | B20: 13565 | C20: 14302 | D20: =ROUND(B20/$B$6*100,1) -> 0.8 | E20: 9.243 | F20: 9.7
A21: от болезней органов дыхания | B21: 59188 | C21: 61150 | D21: =ROUND(B21/$B$6*100,1) -> 3.3 | E21: 40.329 | F21: 41.6
A22: из них от пневмонии | B22: 23912 | C22: 25642 | D22: =ROUND(B22/$B$6*100,1) -> 1.3 | E22: 16.293 | F22: 17.5
A23: от болезней органов пищеварения | B23: 98271 | C23: 95430 | D23: =ROUND(B23/$B$6*100,1) -> 5.5 | E23: 66.958 | F23: 65
A24: из них от язвенной болезни (всех форм) | B24: 10858 | C24: 10730 | D24: =ROUND(B24/$B$6*100,1) -> 0.6 | E24: 7.398 | F24: 7.3
A25: от некоторых инфекционных и паразитарных болезней | B25: 32918 | C25: 34626 | D25: =ROUND(B25/$B$6*100,1) -> 1.8 | E25: 22.429 | F25: 23.6
A26: из них от:
A27: кишечных инфекций | B27: 300 | C27: 283 | D27: 0.02 | E27: 0.204 | F27: 0.2
A28: туберкулеза (всех форм) | B28: 7536 | C28: 8617 | D28: =ROUND(B28/$B$6*100,1) -> 0.4 | E28: 5.135 | F28: 5.9
A29: болезни, вызванной вирусом иммунодефицита человека (ВИЧ) | B29: 20088 | C29: 20597 | D29: =ROUND(B29/$B$6*100,1) -> 1.1 | E29: 13.687 | F29: 14
A30: от болезней мочеполовой системы | B30: 21964 | C30: 20683 | D30: =ROUND(B30/$B$6*100,1) -> 1.2 | E30: 14.965 | F30: 14.1
A31: от болезней нервной системы | B31: 101118 | C31: 110119 | D31: =ROUND(B31/$B$6*100,1) -> 5.6 | E31: 68.898 | F31: 75
A32: от болезней глаза и его придаточного аппарата | B32: 4 | C32: 6 | D32: =ROUND(B32/$B$6*100,5) -> 0.00022 | E32: 0.003 | F32: 0.004
A33: от болезней уха и сосцевидного отростка | B33: 191 | C33: 217 | D33: =ROUND(B33/$B$6*100,4) -> 0.0106 | E33: 0.13 | F33: 0.1
A34: от болезней эндокринной системы, расстройства питания и нарушения обмена веществ | B34: 43852 | C34: 43075 | D34: =ROUND(B34/$B$6*100,1) -> 2.4 | E34: 29.879 | F34: 29.3
A35: из них от сахарного диабета | B35: 41153 | C35: 40257 | D35: =ROUND(B35/$B$6*100,1) -> 2.3 | E35: 28.04 | F35: 27.4
A36: от психических расстройств и расстройства поведения | B36: 19440 | C36: 20619 | D36: =ROUND(B36/$B$6*100,1) -> 1.1 | E36: 13.246 | F36: 14
A37: от болезней костно-мышечной системы и соединительной ткани | B37: 6052 | C37: 5543 | D37: =ROUND(B37/$B$6*100,1) -> 0.3 | E37: 4.124 | F37: 3.8
A38: от болезней крови, кроветворных органов и отдельных нарушений с вовлечением иммунного механизма | B38: 1762 | C38: 1709 | D38: =ROUND(B38/$B$6*100,1) -> 0.1 | E38: 1.201 | F38: 1.2
A39: из них от анемий | B39: 1109 | C39: 1081 | D39: =ROUND(B39/$B$6*100,1) -> 0.1 | E39: 0.756 | F39: 0.7
A40: от болезней кожи и подкожной клетчатки | B40: 3570 | C40: 3583 | D40: =ROUND(B40/$B$6*100,1) -> 0.2 | E40: 2.432 | F40: 2.4
A41: от осложнений беременности, родов и послеродового периода | B41: 134 | C41: 147 | D41: =ROUND(B41/$B$6*100,2) -> 0.01 | E41: 0.091 | F41: 0.1
A42: из них от материнской смертности | B42: 134 | C42: 146 | D42: =ROUND(B42/$B$6*100,2) -> 0.01 | E42: 9,0 1) | F42: 9,1 1)
...

Sheet ТАБ_9
A1: 9. УМЕРШИЕ ПО ОСНОВНЫМ КЛАССАМ ПРИЧИН СМЕРТИ ПО СУБЪЕКТАМ РОССИЙСКОЙ ФЕДЕРАЦИИ
A2: ЗА 2019 ГОД | D2: ЗА | E2: 1998 год
B4: Всего умерших | C4: в том числе от:
C5: некоторых инфекционных и паразитарных болезней | D5: в том числе от туберкулеза | E5: новообразо-ваний | F5: болезней системы кровообраще-ния | G5: болезней органов дыхания | H5: болезней органов пищеварения | I5: внешних причин
A6: РОССИЙСКАЯ ФЕДЕРАЦИЯ | B6: 1798307 | C6: 32918 | D6: 7536 | E6: 298699 | F6: 841207 | G6: 59188 | H6: 98271 | I6: 137633
A7: Центральный федеральный округ | B7: 496740 | C7: 4435 | D7: 887 | E7: 83335 | F7: 227487 | G7: 14862 | H7: 25730 | I7: 31393
A8: Белгородская область | B8: 20662 | C8: 81 | D8: 10 | E8: 2850 | F8: 10291 | G8: 862 | H8: 924 | I8: 1163
A9: Брянская область | B9: 17615 | C9: 125 | D9: 51 | E9: 2954 | F9: 8415 | G9: 788 | H9: 1023 | I9: 1226
A10: Владимирская область | B10: 21183 | C10: 155 | D10: 32 | E10: 3445 | F10: 10829 | G10: 637 | H10: 1564 | I10: 1400
A11: Воронежская область | B11: 32882 | C11: 159 | D11: 48 | E11: 4172 | F11: 13989 | G11: 749 | H11: 1218 | I11: 1875
A12: Ивановская область | B12: 15799 | C12: 143 | D12: 19 | E12: 2304 | F12: 6306 | G12: 507 | H12: 1033 | I12: 883
A13: Калужская область | B13: 14656 | C13: 132 | D13: 10 | E13: 2388 | F13: 7064 | G13: 652 | H13: 805 | I13: 1021
A14: Костромская область | B14: 9337 | C14: 49 | D14: 4 | E14: 1625 | F14: 5001 | G14: 215 | H14: 484 | I14: 587
A15: Курская область | B15: 16562 | C15: 83 | D15: 46 | E15: 2636 | F15: 7627 | G15: 859 | H15: 813 | I15: 993
A16: Липецкая область | B16: 16291 | C16: 47 | D16: 17 | E16: 2153 | F16: 6523 | G16: 618 | H16: 644 | I16: 1117
A17: Московская область | B17: 91448 | C17: 939 | D17: 154 | E17: 13686 | F17: 36218 | G17: 2363 | H17: 5158 | I17: 6951
... A101: Чукотский автономный округ | B101: 454 | C101: 24 | D101: 13 | E101: 67 | F101: 194 | G101: 18 | H101: 23 | I101: 93

Sheet ТАБ_10
A1: 10. СМЕРТНОСТЬ НАСЕЛЕНИЯ ПО ОСНОВНЫМ КЛАССАМ ПРИЧИН СМЕРТИ ПО СУБЪЕКТАМ РОССИЙСКОЙ ФЕДЕРАЦИИ
A2: ЗА 2019 ГОД | D2: ЗА | E2: 1998 год
A3: ( на 100 000 человек населения )
B4: Всего умерших | C4: в том числе от:
C5: некоторых инфекционных и паразитарных болезней | D5: в том числе от туберкулеза | E5: новообразо-ваний | F5: болезней системы кровообраще-ния | G5: болезней органов дыхания | H5: болезней органов пищеварения | I5: внешних причин
A6: РОССИЙСКАЯ ФЕДЕРАЦИЯ | B6: 1225.3 | C6: 22.429 | D6: 5.135 | E6: 203.522 | F6: 573.167 | G6: 40.329 | H6: 66.958 | I6: 93.778
A7: Центральный федеральный округ | B7: 1260.576 | C7: 11.255 | D7: 2.251 | E7: 211.479 | F7: 577.293 | G7: 37.715 | H7: 65.295 | I7: 79.666
A8: Белгородская область | B8: 1334.51 | C8: 5.232 | D8: 0.646 | E8: 184.075 | F8: 664.671 | G8: 55.675 | H8: 59.679 | I8: 75.115
A9: Брянская область | B9: 1472.409 | C9: 10.449 | D9: 4.263 | E9: 246.92 | F9: 703.396 | G9: 65.868 | H9: 85.511 | I9: 102.479
A10: Владимирская область | B10: 1555.161 | C10: 11.379 | D10: 2.349 | E10: 252.916 | F10: 795.017 | G10: 46.766 | H10: 114.822 | I10: 102.782
A11: Воронежская область | B11: 1413.664 | C11: 6.836 | D11: 2.064 | E11: 179.363 | F11: 601.415 | G11: 32.201 | H11: 52.364 | I11: 80.61
A12: Ивановская область | B12: 1578.861 | C12: 14.291 | D12: 1.899 | E12: 230.248 | F12: 630.185 | G12: 50.667 | H12: 103.232 | I12: 88.242
A13: Калужская область | B13: 1456.891 | C13: 13.122 | D13: 0.994 | E13: 237.381 | F13: 702.202 | G13: 64.813 | H13: 80.022 | I13: 101.493
A14: Костромская область | B14: 1469.639 | C14: 7.713 | D14: 0.63 | E14: 255.774 | F14: 787.155 | G14: 33.841 | H14: 76.181 | I14: 92.394
A15: Курская область | B15: 1498.113 | C15: 7.508 | D15: 4.161 | E15: 238.439 | F15: 689.899 | G15: 77.701 | H15: 73.54 | I15: 89.822
A16: Липецкая область | B16: 1426.903 | C16: 4.117 | D16: 1.489 | E16: 188.578 | F16: 571.339 | G16: 54.13 | H16: 56.407 | I16: 97.836
A17: Московская область | B17: 1196.141 | C17: 12.282 | D17: 2.014 | E17: 179.013 | F17: 473.732 | G17: 30.908 | H17: 67.467 | I17: 90.919
... A101: Чукотский автономный округ | B101: 908.454 | C101: 48.024 | D101: 26.013 | E101: 134.067 | F101: 388.194 | G101: 36.018 | H101: 46.023 | I101: 186.093

Sheet ТАБ_11
A1: 11. ЧИСЛО УМЕРШИХ ОТ ВНЕШНИХ ПРИЧИН СМЕРТИ ПО СУБЪЕКТАМ РОССИЙСКОЙ ФЕДЕРАЦИИ
A2: ЗА 2019 ГОД
B4: Всего умерших | C4: в том числе от :
C5: всех видов транспортных несчастных случаев | D5: из них от ДТП | E5: причин смерти, обусловленных алкоголем | F5: случайных утоплений | G5: самоубийств | H5: убийств
A6: РОССИЙСКАЯ ФЕДЕРАЦИЯ | B6: 137633 | C6: 17787 | D6: 13565 | E6: 47427 | F6: 4068 | G6: 17192 | H6: 7302
A7: Центральный федеральный округ | B7: 31393 | C7: 4731 | D7: 3249 | E7: 15785 | F7: 770 | G7: 3221 | H7: 1524
A8: Белгородская область | B8: 1163 | C8: 201 | D8: 170 | E8: 226 | F8: 37 | G8: 171 | H8: 53
A9: Брянская область | B9: 1226 | C9: 152 | D9: 121 | E9: 468 | F9: 45 | G9: 135 | H9: 79
A10: Владимирская область | B10: 1400 | C10: 259 | D10: 206 | E10: 701 | F10: 26 | G10: 195 | H10: 92
A11: Воронежская область | B11: 1875 | C11: 376 | D11: 316 | E11: 1067 | F11: 66 | G11: 258 | H11: 69
A12: Ивановская область | B12: 883 | C12: 104 | D12: 95 | E12: 718 | F12: 28 | G12: 172 | H12: 68
A13: Калужская область | B13: 1021 | C13: 163 | D13: 116 | E13: 604 | F13: 31 | G13: 120 | H13: 48
A14: Костромская область | B14: 587 | C14: 77 | D14: 67 | E14: 153 | F14: 18 | G14: 117 | H14: 32
A15: Курская область | B15: 993 | C15: 200 | D15: 167 | E15: 333 | F15: 41 | G15: 121 | H15: 43
A16: Липецкая область | B16: 1117 | C16: 158 | D16: 83 | E16: 720 | F16: 5 | G16: 27 | H16: 35
A17: Московская область | B17: 6951 | C17: 988 | D17: 588 | E17: 4359 | F17: 174 | G17: 879 | H17: 450
... A101: Чукотский автономный округ | B101: 93 | C101: 2 | D101: 0 | E101: 38 | F101: 7 | G101: 9 | H101: 15

Sheet ТАБ_12
A1: 12. СМЕРТНОСТЬ НАСЕЛЕНИЯ ОТ ВНЕШНИХ ПРИЧИН СМЕРТИ ПО СУБЪЕКТАМ РОССИЙСКОЙ ФЕДЕРАЦИИ
A2: ЗА 2019 ГОД
A3: ( на 100 000 человек населения )
B4: Всего умерших | C4: в том числе от :
C5: всех видов транспортных несчастных случаев | D5: из них от ДТП | E5: причин смерти, обусловленных алкоголем | F5: случайных утоплений | G5: самоубийств | H5: убийств
A6: РОССИЙСКАЯ ФЕДЕРАЦИЯ | B6: 93.778 | C6: 12.119 | D6: 9.243 | E6: 32.315 | F6: 2.772 | G6: 11.714 | H6: 4.975
A7: Центральный федеральный округ | B7: 79.666 | C7: 12.006 | D7: 8.245 | E7: 40.058 | F7: 1.954 | G7: 8.174 | H7: 3.867
A8: Белгородская область | B8: 75.115 | C8: 12.982 | D8: 10.98 | E8: 14.597 | F8: 2.39 | G8: 11.044 | H8: 3.423
A9: Брянская область | B9: 102.479 | C9: 12.705 | D9: 10.114 | E9: 39.119 | F9: 3.761 | G9: 11.284 | H9: 6.603
A10: Владимирская область | B10: 102.782 | C10: 19.015 | D10: 15.124 | E10: 51.464 | F10: 1.909 | G10: 14.316 | H10: 6.754
A11: Воронежская область | B11: 80.61 | C11: 16.165 | D11: 13.585 | E11: 45.872 | F11: 2.837 | G11: 11.092 | H11: 2.966
A12: Ивановская область | B12: 88.242 | C12: 10.393 | D12: 9.494 | E12: 71.753 | F12: 2.798 | G12: 17.189 | H12: 6.796
A13: Калужская область | B13: 101.493 | C13: 16.203 | D13: 11.531 | E13: 60.041 | F13: 3.082 | G13: 11.929 | H13: 4.771
A14: Костромская область | B14: 92.394 | C14: 12.12 | D14: 10.546 | E14: 24.082 | F14: 2.833 | G14: 18.416 | H14: 5.037
A15: Курская область | B15: 89.822 | C15: 18.091 | D15: 15.106 | E15: 30.121 | F15: 3.709 | G15: 10.945 | H15: 3.89
A16: Липецкая область | B16: 97.836 | C16: 13.839 | D16: 7.27 | E16: 63.064 | F16: 0.438 | G16: 2.365 | H16: 3.066
A17: Московская область | B17: 90.919 | C17: 12.923 | D17: 7.691 | E17: 57.016 | F17: 2.276 | G17: 11.497 | H17: 5.886
... A101: Чукотский автономный округ | B101: 186.1 | C101: 4 | D101: 0 | E101: 76 | F101: 14 | G101: 18 | H101: 30

Sheet ТАБ_13
A1: 13. УМЕРШИЕ ПО ВОЗРАСТНЫМ ГРУППАМ И ОСНОВНЫМ КЛАССАМ ПРИЧИН СМЕРТИ В 2019 ГОДУ
A3: Возраст | B3: Всего умерших | C3: в том числе от:
C4: некоторых инфекционных и паразитарных болезней | D4: в том числе от туберкулеза | E4: новообразова-ний | F4: болезней системы кровообраще-ния | G4: болезней органов дыхания | H4: болезней органов пищеварения | I4: внешних причин
A5: до 1 года | B5: 7328 | C5: 287 | D5: 0 | E5: 61 | F5: 100 | G5: 344 | H5: 41 | I5: 413
A6: 0-27 дней | B6: 4039 | C6: 17 | D6: 0 | E6: 7 | F6: 7 | G6: 22 | H6: 1 | I6: 59
A7: 1 | B7: 759 | C7: 76 | D7: 2 | E7: 59 | F7: 22 | G7: 83 | H7: 10 | I7: 206
A8: 2 | B8: 484 | C8: 43 | D8: 1 | E8: 62 | F8: 14 | G8: 30 | H8: 4 | I8: 169
A9: 3 | B9: 434 | C9: 19 | D9: 0 | E9: 81 | F9: 6 | G9: 26 | H9: 1 | I9: 164
A10: 4 | B10: 378 | C10: 23 | D10: 0 | E10: 54 | F10: 8 | G10: 21 | H10: 2 | I10: 148
A11: 1-4 | B11: 2055 | C11: 161 | D11: 3 | E11: 256 | F11: 50 | G11: 160 | H11: 17 | I11: 687
A12: 5-9 | B12: 1497 | C12: 40 | D12: 2 | E12: 242 | F12: 45 | G12: 64 | H12: 18 | I12: 627
A13: 10-14 | B13: 1737 | C13: 20 | D13: 1 | E13: 188 | F13: 87 | G13: 73 | H13: 23 | I13: 860
A14: 15-19 | B14: 4017 | C14: 40 | D14: 5 | E14: 251 | F14: 242 | G14: 74 | H14: 48 | I14: 2702
A15: 20-24 | B15: 6587 | C15: 215 | D15: 46 | E15: 348 | F15: 555 | G15: 115 | H15: 114 | I15: 4429
A16: 25-29 | B16: 13389 | C16: 1423 | D16: 216 | E16: 768 | F16: 1533 | G16: 305 | H16: 699 | I16: 7203
A17: 30-34 | B17: 30141 | C17: 4374 | D17: 614 | E17: 2018 | F17: 4753 | G17: 902 | H17: 2619 | I17: 12275
A18: 35-39 | B18: 44562 | C18: 7035 | D18: 855 | E18: 3693 | F18: 8679 | G18: 1538 | H18: 5040 | I18: 13954
A19: 40-44 | B19: 55050 | C19: 6228 | D19: 992 | E19: 6177 | F19: 13813 | G19: 2068 | H19: 6900 | I19: 14045
A20: 45-49 | B20: 61966 | C20: 3862 | D20: 936 | E20: 9767 | F20: 19500 | G20: 2348 | H20: 7253 | I20: 12534
A21: 50-54 | B21: 75760 | C21: 2456 | D21: 899 | E21: 15585 | F21: 27532 | G21: 2875 | H21: 7704 | I21: 11508
A22: 55-59 | B22: 127687 | C22: 2116 | D22: 941 | E22: 31361 | F22: 51320 | G22: 4651 | H22: 10944 | I22: 13788
... A31: в т.ч. в трудоспособном возрасте | B31: 379433 | C31: 27113 | D31: 5315 | E31: 57587 | F31: 114445 | G31: 13888 | H31: 37041 | I31: 89343

Sheet ТАБ_14
A1: 14. МАТЕРИНСКАЯ СМЕРТНОСТЬ ПО СУБЪЕКТАМ РОССИЙСКОЙ ФЕДЕРАЦИИ
B3: 2019 г. | C3: 2018 г. | D3: на 100000 родившихся живыми
D4: 2019 г. | E4: 2018 г.
A5: РОССИЙСКАЯ ФЕДЕРАЦИЯ | B5: 134 | C5: 146 | D5: 9 | E5: 9.1
A6: Центральный федеральный округ | B6: 37 | C6: 37 | D6: 10.1 | E6: 9.5
A7: Белгородская область | B7: 0 | C7: 1 | D7: 0 | E7: 7
A8: Брянская область | B8: 1 | C8: 3 | D8: 10 | E8: 27
A9: Владимирская область | B9: 2 | C9: 0 | D9: 18 | E9: 0
A10: Воронежская область | B10: 0 | C10: 1 | D10: 0 | E10: 4.7
A11: Ивановская область | B11: 1 | C11: 0 | D11: 12.6 | E11: 0
A12: Калужская область | B12: 0 | C12: 0 | D12: 0 | E12: 0
A13: Костромская область | B13: 2 | C13: 3 | D13: 34.7 | E13: 48.1
A14: Курская область | B14: 2 | C14: 0 | D14: 21.6 | E14: 0
A15: Липецкая область | B15: 0 | C15: 0 | D15: 0 | E15: 0
A16: Московская область | B16: 5 | C16: 3 | D16: 6.9 | E16: 3.6
... A100: Чукотский автономный округ | B100: 0 | C100: 0 | D100: 0 | E100: 0

Sheet ТАБ_15
A1: 15. ПЕРИНАТАЛЬНАЯ СМЕРТНОСТЬ ПО СУБЪЕКТАМ РОССИЙСКОЙ ФЕДЕРАЦИИ ЗА 2019 ГОД
B3: человек | E3: на 1000 родившихся живыми и мертвыми | G3: на 1000 родившихся живыми
B4: всего | C4: мертво- рожденные | D4: умершие в возрасте до 7 дней | E4: всего | F4: мертво- рожденные | G4: умершие в возрасте до 7 дней
A5: РОССИЙСКАЯ ФЕДЕРАЦИЯ | B5: =C5+D5 -> 10576 | C5: 8101 | D5: 2475 | E5: 7.1 | F5: 5.44 | G5: 1.67
A6: Центральный федеральный округ | B6: =C6+D6 -> 2280 | C6: 1800 | D6: 480 | E6: 6.19 | F6: 4.89 | G6: 1.31
A7: Белгородская область | B7: =C7+D7 -> 67 | C7: 50 | D7: 17 | E7: 5.06 | F7: 3.78 | G7: 1.29
A8: Брянская область | B8: =C8+D8 -> 71 | C8: 58 | D8: 13 | E8: 7.09 | F8: 5.79 | G8: 1.31
A9: Владимирская область | B9: =C9+D9 -> 107 | C9: 81 | D9: 26 | E9: 9.57 | F9: 7.24 | G9: 2.34
A10: Воронежская область | B10: =C10+D10 -> 131 | C10: 97 | D10: 34 | E10: 6.66 | F10: 4.93 | G10: 1.74
A11: Ивановская область | B11: =C11+D11 -> 68 | C11: 56 | D11: 12 | E11: 8.51 | F11: 7.01 | G11: 1.51
A12: Калужская область | B12: =C12+D12 -> 70 | C12: 62 | D12: 8 | E12: 7.79 | F12: 6.9 | G12: 0.9
A13: Костромская область | B13: =C13+D13 -> 46 | C13: 33 | D13: 13 | E13: 7.94 | F13: 5.7 | G13: 2.26
A14: Курская область | B14: =C14+D14 -> 48 | C14: 39 | D14: 9 | E14: 5.17 | F14: 4.2 | G14: 0.97
A15: Липецкая область | B15: =C15+D15 -> 64 | C15: 57 | D15: 7 | E15: 6.5 | F15: 5.79 | G15: 0.72
A16: Московская область | B16: =C16+D16 -> 381 | C16: 306 | D16: 75 | E16: 5.24 | F16: 4.2 | G16: 1.03
... A100: Чукотский автономный округ | B100: =C100+D100 -> 5 | C100: 3 | D100: 2 | E100: 9.47 | F100: 5.68 | G100: 3.81

Sheet ТАБ_16
A1: 16. МЛАДЕНЧЕСКАЯ СМЕРТНОСТЬ ПО СУБЪЕКТАМ РОССИЙСКОЙ ФЕДЕРАЦИИ
B3: Число детей, умерших в возрасте до 1 года | E3: Число детей, умерших в возрасте до 1 года, на 1000 родившихся живыми
B5: 2019 г. | C5: 2018г. | D5: Прирост, снижение / - / | E5: 2019 г. | F5: 2018 г.
A6: РОССИЙСКАЯ ФЕДЕРАЦИЯ | B6: 7328 | C6: 8244 | D6: =B6-C6 -> -916 | E6: 4.9 | F6: 5.1
A7: Центральный федеральный округ | B7: 1620 | C7: 1884 | D7: =B7-C7 -> -264 | E7: 4.4 | F7: 4.8
A8: Белгородская область | B8: 39 | C8: 73 | D8: =B8-C8 -> -34 | E8: 2.9 | F8: 5.1
A9: Брянская область | B9: 37 | C9: 45 | D9: =B9-C9 -> -8 | E9: 3.6 | F9: 4
A10: Владимирская область | B10: 58 | C10: 67 | D10: =B10-C10 -> -9 | E10: 5.1 | F10: 5.2
A11: Воронежская область | B11: 81 | C11: 99 | D11: =B11-C11 -> -18 | E11: 4.1 | F11: 4.6
A12: Ивановская область | B12: 40 | C12: 35 | D12: =B12-C12 -> 5 | E12: 4.9 | F12: 3.8
A13: Калужская область | B13: 36 | C13: 51 | D13: =B13-C13 -> -15 | E13: 3.9 | F13: 4.9
A14: Костромская область | B14: 43 | C14: 35 | D14: =B14-C14 -> 8 | E14: 7.3 | F14: 5.6
A15: Курская область | B15: 41 | C15: 55 | D15: =B15-C15 -> -14 | E15: 4.3 | F15: 5.3
A16: Липецкая область | B16: 29 | C16: 39 | D16: =B16-C16 -> -10 | E16: 2.9 | F16: 3.6
A17: Московская область | B17: 296 | C17: 341 | D17: =B17-C17 -> -45 | E17: 4 | F17: 4.1
... A101: Чукотский автономный округ | B101: 6 | C101: 8 | D101: =B101-C101 -> -2 | E101: 10.5 | F101: 12.7

Sheet ТАБ_17
A1: 17. МЛАДЕНЧЕСКАЯ СМЕРТНОСТЬ В РОССИЙСКОЙ ФЕДЕРАЦИИ ПО ОСНОВНЫМ КЛАССАМ И ОТДЕЛЬНЫМ ПРИЧИНАМ СМЕРТИ
B3: Число детей, умерших в возрасте до 1 года | E3: Число детей, умерших в возрасте до 1 года, на 10000 родившихся живыми
B5: 2019 г. | C5: 2018 г. | D5: в % к общему числу умерших в 2019 г. | E5: 2019 г. | F5: 2018 г.
A6: Всего умерших от всех причин | B6: 7328 | C6: 8244 | D6: =ROUND(B6/$B$6*100,1) -> 100 | E6: 48.8 | F6: 50.9
A7: в том числе:
A8: от некоторых инфекционных и паразитарных болезней | B8: 287 | C8: 363 | D8: =ROUND(B8/$B$6*100,1) -> 3.9 | E8: 1.9 | F8: 2.2
A9: из них от:
A10: кишечных инфекций | B10: 38 | C10: 45 | D10: =ROUND(B10/$B$6*100,1) -> 0.5 | E10: 0.3 | F10: 0.3
A11: септицемии | B11: 55 | C11: 88 | D11: =ROUND(B11/$B$6*100,1) -> 0.8 | E11: 0.4 | F11: 0.5
A12: от болезней эндокринной системы, расстройства питания и нарушения обмена веществ | B12: 76 | C12: 65 | D12: =ROUND(B12/$B$6*100,1) -> 1 | E12: 0.5 | F12: 0.4
A13: от болезней нервной системы | B13: 248 | C13: 243 | D13: =ROUND(B13/$B$6*100,1) -> 3.4 | E13: 1.7 | F13: 1.5
A14: из них от менингита, за исключением менингита при инфекционных и паразитарных заболеваниях | B14: 20 | C14: 25 | D14: =ROUND(B14/$B$6*100,1) -> 0.3 | E14: 0.1 | F14: 0.2
A15: от болезней органов дыхания | B15: 344 | C15: 384 | D15: =ROUND(B15/$B$6*100,1) -> 4.7 | E15: 2.3 | F15: 2.4
A16: из них от:
A17: пневмонии | B17: 214 | C17: 227 | D17: =ROUND(B17/$B$6*100,1) -> 2.9 | E17: 1.4 | F17: 1.4
A18: гриппа и ОРЗ | B18: 82 | C18: 116 | D18: =ROUND(B18/$B$6*100,1) -> 1.1 | E18: 0.5 | F18: 0.7
A19: от болезней органов пищеварения | B19: 41 | C19: 48 | D19: =ROUND(B19/$B$6*100,1) -> 0.6 | E19: 0.3 | F19: 0.3
A20: от врожденных аномалий (пороков развития), деформаций и хромосомных нарушений | B20: 1551 | C20: 1842 | D20: =ROUND(B20/$B$6*100,1) -> 21.2 | E20: 10.3 | F20: 11.4
A21: из них от:
A22: врожденной гидроцефалии и spina bifida | B22: 40 | C22: 71 | D22: =ROUND(B22/$B$6*100,1) -> 0.5 | E22: 0.3 | F22: 0.4
A23: врожденных аномалий системы кровообращения | B23: 706 | C23: 805 | D23: =ROUND(B23/$B$6*100,1) -> 9.6 | E23: 4.7 | F23: 5
A24: от отдельных состояний, возникающих в перинатальном периоде | B24: 3755 | C24: 4106 | D24: =ROUND(B24/$B$6*100,1) -> 51.2 | E24: 25 | F24: 25.3
A25: из них от:
A26: родовых травм | B26: 23 | C26: 41 | D26: =ROUND(B26/$B$6*100,1) -> 0.3 | E26: 0.2 | F26: 0.3
A27: внутриутробной гипоксии и асфиксии в родах | B27: 262 | C27: 290 | D27: =ROUND(B27/$B$6*100,1) -> 3.6 | E27: 1.7 | F27: 1.8
A28: дыхательных расстройств новорожденного | B28: 529 | C28: 556 | D28: =ROUND(B28/$B$6*100,1) -> 7.2 | E28: 3.5 | F28: 3.4
A29: бактериального сепсиса новорожденного | B29: 463 | C29: 536 | D29: =ROUND(B29/$B$6*100,1) -> 6.3 | E29: 3.1 | F29: 3.3
A30: геморрагических нарушений у плода и новорожденного | B30: 672 | C30: 729 | D30: =ROUND(B30/$B$6*100,1) -> 9.2 | E30: 4.5 | F30: 4.5
A31: от внешних причин смерти | B31: 413 | C31: 535 | D31: =ROUND(B31/$B$6*100,1) -> 5.6 | E31: 2.7 | F31: 3.3

Sheet ТАБ_18
A1: 18. УМЕРШИЕ В ВОЗРАСТЕ ДО 1 ГОДА ПО ОСНОВНЫМ КЛАССАМ ПРИЧИН СМЕРТИ
A2: ПО СУБЪЕКТАМ РОССИЙСКОЙ ФЕДЕРАЦИИ ЗА 2019 ГОД
C3: ЗА 1998 год | D3: за | E3: 1998 год
B4: Всего умерших | C4: из них от:
C5: отдельных состояний, возникающих в перинатальном периоде | D5: врожденных аномалий (пороков развития) | E5: болезней органов дыхания | F5: некоторых инфекционных и паразитарных болезней | G5: внешних причин | H5: болезней органов пищеварения
A6: РОССИЙСКАЯ ФЕДЕРАЦИЯ | B6: 7328 | C6: 3755 | D6: 1551 | E6: 344 | F6: 287 | G6: 413 | H6: 41
A7: Центральный федеральный округ | B7: 1620 | C7: 780 | D7: 489 | E7: 60 | F7: 36 | G7: 65 | H7: 4
A8: Белгородская область | B8: 39 | C8: 25 | D8: 5 | E8: 1 | F8: 3 | G8: 1 | H8: 0
A9: Брянская область | B9: 37 | C9: 12 | D9: 8 | E9: 9 | F9: 1 | G9: 2 | H9: 0
A10: Владимирская область | B10: 58 | C10: 37 | D10: 12 | E10: 3 | F10: 2 | G10: 3 | H10: 0
A11: Воронежская область | B11: 81 | C11: 41 | D11: 20 | E11: 0 | F11: 3 | G11: 1 | H11: 1
A12: Ивановская область | B12: 40 | C12: 16 | D12: 13 | E12: 0 | F12: 0 | G12: 3 | H12: 0
A13: Калужская область | B13: 36 | C13: 9 | D13: 15 | E13: 3 | F13: 3 | G13: 2 | H13: 0
A14: Костромская область | B14: 43 | C14: 28 | D14: 4 | E14: 1 | F14: 1 | G14: 1 | H14: 0
A15: Курская область | B15: 41 | C15: 15 | D15: 6 | E15: 5 | F15: 2 | G15: 6 | H15: 0
A16: Липецкая область | B16: 29 | C16: 15 | D16: 4 | E16: 4 | F16: 0 | G16: 2 | H16: 0
A17: Московская область | B17: 296 | C17: 159 | D17: 70 | E17: 17 | F17: 6 | G17: 14 | H17: 2
... A101: Чукотский автономный округ | B101: 6 | C101: 3 | D101: 0 | E101: 0 | F101: 1 | G101: 2 | H101: 0

Sheet ТАБ_19
A1: 19. КОЭФФИЦИЕНТЫ МЛАДЕНЧЕСКОЙ СМЕРТНОСТИ ПО ОСНОВНЫМ КЛАССАМ ПРИЧИН СМЕРТИ
A2: ПО СУБЪЕКТАМ РОССИЙСКОЙ ФЕДЕРАЦИИ ЗА 2019 ГОД
A3: ( на 10 000 родившихся живыми ) | C3: за | D3: 1998 год
B4: Всего умерших | C4: из них от:
C5: отдельных состояний, возникающих в перинатальном периоде | D5: врожденных аномалий(пороков развития) | E5: болезней органов дыхания | F5: некоторых инфекционных и паразитарных болезней | G5: внешних причин | H5: болезней органов пищеварения
A6: РОССИЙСКАЯ ФЕДЕРАЦИЯ | B6: 48.761 | C6: 24.986 | D6: 10.32 | E6: 2.289 | F6: 1.91 | G6: 2.748 | H6: 0.273
A7: Центральный федеральный округ | B7: 43.668 | C7: 21.025 | D7: 13.181 | E7: 1.617 | F7: 0.97 | G7: 1.752 | H7: 0.108
A8: Белгородская область | B8: 29.103 | C8: 18.656 | D8: 3.731 | E8: 0.746 | F8: 2.239 | G8: 0.746 | H8: 0
A9: Брянская область | B9: 36.422 | C9: 11.813 | D9: 7.875 | E9: 8.86 | F9: 0.984 | G9: 1.969 | H9: 0
A10: Владимирская область | B10: 50.892 | C10: 32.465 | D10: 10.529 | E10: 2.632 | F10: 1.755 | G10: 2.632 | H10: 0
A11: Воронежская область | B11: 40.927 | C11: 20.716 | D11: 10.105 | E11: 0 | F11: 1.516 | G11: 0.505 | H11: 0.505
A12: Ивановская область | B12: 48.761 | C12: 19.505 | D12: 15.847 | E12: 0 | F12: 0 | G12: 3.657 | H12: 0
A13: Калужская область | B13: 38.792 | C13: 9.698 | D13: 16.163 | E13: 3.233 | F13: 3.233 | G13: 2.155 | H13: 0
A14: Костромская область | B14: 73.464 | C14: 47.837 | D14: 6.834 | E14: 1.708 | F14: 1.708 | G14: 1.708 | H14: 0
A15: Курская область | B15: 43.385 | C15: 15.873 | D15: 6.349 | E15: 5.291 | F15: 2.116 | G15: 6.349 | H15: 0
A16: Липецкая область | B16: 28.805 | C16: 14.899 | D16: 3.973 | E16: 3.973 | F16: 0 | G16: 1.987 | H16: 0
A17: Московская область | B17: 39.876 | C17: 21.42 | D17: 9.43 | E17: 2.29 | F17: 0.808 | G17: 1.886 | H17: 0.269
... A101: Чукотский автономный округ | B101: 105.143 | C101: 52.571 | D101: 0 | E101: 0 | F101: 17.524 | G101: 35.048 | H101: 0

Sheet ТАБ_20
A1: 20. ЧИСЛО БРАКОВ И РАЗВОДОВ ПО СУБЪЕКТАМ РОССИЙСКОЙ ФЕДЕРАЦИИ
B3: Число браков | D3: Прирост, снижение / - / | E3: Число разводов | G3: Прирост, снижение / - /
B4: 2019 г. | C4: 2018 г. | E4: 2019 г. | F4: 2018 г.
A5: РОССИЙСКАЯ ФЕДЕРАЦИЯ | B5: 950167 | C5: 893039 | D5: =B5-C5 -> 57128 | E5: 620730 | F5: 583942 | G5: =E5-F5 -> 36788
A6: Центральный федеральный округ | B6: 259596 | C6: 239993 | D6: =B6-C6 -> 19603 | E6: 168393 | F6: 153515 | G6: =E6-F6 -> 14878
A7: Белгородская область | B7: 10338 | C7: 10432 | D7: =B7-C7 -> -94 | E7: 6519 | F7: 6753 | G7: =E7-F7 -> -234
A8: Брянская область | B8: 7754 | C8: 7278 | D8: =B8-C8 -> 476 | E8: 5406 | F8: 5401 | G8: =E8-F8 -> 5
A9: Владимирская область | B9: 8166 | C9: 8121 | D9: =B9-C9 -> 45 | E9: 5503 | F9: 5508 | G9: =E9-F9 -> -5
A10: Воронежская область | B10: 16039 | C10: 14525 | D10: =B10-C10 -> 1514 | E10: 10138 | F10: 9652 | G10: =E10-F10 -> 486
A11: Ивановская область | B11: 5694 | C11: 5674 | D11: =B11-C11 -> 20 | E11: 4082 | F11: 3961 | G11: =E11-F11 -> 121
A12: Калужская область | B12: 7162 | C12: 6562 | D12: =B12-C12 -> 600 | E12: 4922 | F12: 4468 | G12: =E12-F12 -> 454
A13: Костромская область | B13: 3592 | C13: 3606 | D13: =B13-C13 -> -14 | E13: 2807 | F13: 2582 | G13: =E13-F13 -> 225
A14: Курская область | B14: 7175 | C14: 6957 | D14: =B14-C14 -> 218 | E14: 4871 | F14: 4936 | G14: =E14-F14 -> -65
A15: Липецкая область | B15: 7056 | C15: 6745 | D15: =B15-C15 -> 311 | E15: 4914 | F15: 4706 | G15: =E15-F15 -> 208
A16: Московская область | B16: 56223 | C16: 49339 | D16: =B16-C16 -> 6884 | E16: 37500 | F16: 29415 | G16: =E16-F16 -> 8085
... A100: Чукотский автономный округ | B100: 360 | C100: 356 | D100: =B100-C100 -> 4 | E100: 247 | F100: 239 | G100: =E100-F100 -> 8

Sheet ТАБ_21
A1: 21. ОБЩИЕ КОЭФФИЦИЕНТЫ БРАЧНОСТИ И РАЗВОДИМОСТИ ПО СУБЪЕКТАМ РОССИЙСКОЙ ФЕДЕРАЦИИ
B3: На 1000 населения браков | D3: На 1000 населения разводов | F3: Число разводов на 1000 браков
B5: 2019 г. | C5: 2018 г. | D5: 2019 г. | E5: 2018 г. | F5: 2019 г. | G5: 2018 г.
A6: РОССИЙСКАЯ ФЕДЕРАЦИЯ | B6: 6.5 | C6: 6.1 | D6: 4.2 | E6: 4 | F6: =ROUND(ТАБ_20!E5/ТАБ_20!B5*1000,0) -> 653 | G6: =ROUND(ТАБ_20!F5/ТАБ_20!C5*1000,0) -> 654
A7: Центральный федеральный округ | B7: 6.6 | C7: 6.1 | D7: 4.3 | E7: 3.9 | F7: =ROUND(ТАБ_20!E6/ТАБ_20!B6*1000,0) -> 649 | G7: =ROUND(ТАБ_20!F6/ТАБ_20!C6*1000,0) -> 640
A8: Белгородская область | B8: 6.7 | C8: 6.7 | D8: 4.2 | E8: 4.4 | F8: =ROUND(ТАБ_20!E7/ТАБ_20!B7*1000,0) -> 631 | G8: =ROUND(ТАБ_20!F7/ТАБ_20!C7*1000,0) -> 647
A9: Брянская область | B9: 6.5 | C9: 6 | D9: 4.5 | E9: 4.5 | F9: =ROUND(ТАБ_20!E8/ТАБ_20!B8*1000,0) -> 697 | G9: =ROUND(ТАБ_20!F8/ТАБ_20!C8*1000,0) -> 742
A10: Владимирская область | B10: 6 | C10: 5.9 | D10: 4 | E10: 4 | F10: =ROUND(ТАБ_20!E9/ТАБ_20!B9*1000,0) -> 674 | G10: =ROUND(ТАБ_20!F9/ТАБ_20!C9*1000,0) -> 678
A11: Воронежская область | B11: 6.9 | C11: 6.2 | D11: 4.4 | E11: 4.1 | F11: =ROUND(ТАБ_20!E10/ТАБ_20!B10*1000,0) -> 632 | G11: =ROUND(ТАБ_20!F10/ТАБ_20!C10*1000,0) -> 665
A12: Ивановская область | B12: 5.7 | C12: 5.6 | D12: 4.1 | E12: 3.9 | F12: =ROUND(ТАБ_20!E11/ТАБ_20!B11*1000,0) -> 717 | G12: =ROUND(ТАБ_20!F11/ТАБ_20!C11*1000,0) -> 698
A13: Калужская область | B13: 7.1 | C13: 6.5 | D13: 4.9 | E13: 4.4 | F13: =ROUND(ТАБ_20!E12/ТАБ_20!B12*1000,0) -> 687 | G13: =ROUND(ТАБ_20!F12/ТАБ_20!C12*1000,0) -> 681
A14: Костромская область | B14: 5.7 | C14: 5.6 | D14: 4.4 | E14: 4 | F14: =ROUND(ТАБ_20!E13/ТАБ_20!B13*1000,0) -> 781 | G14: =ROUND(ТАБ_20!F13/ТАБ_20!C13*1000,0) -> 716
A15: Курская область | B15: 6.5 | C15: 6.3 | D15: 4.4 | E15: 4.4 | F15: =ROUND(ТАБ_20!E14/ТАБ_20!B14*1000,0) -> 679 | G15: =ROUND(ТАБ_20!F14/ТАБ_20!C14*1000,0) -> 710
A16: Липецкая область | B16: 6.2 | C16: 5.9 | D16: 4.3 | E16: 4.1 | F16: =ROUND(ТАБ_20!E15/ТАБ_20!B15*1000,0) -> 696 | G16: =ROUND(ТАБ_20!F15/ТАБ_20!C15*1000,0) -> 698
A17: Московская область | B17: 7.4 | C17: 6.5 | D17: 4.9 | E17: 3.9 | F17: =ROUND(ТАБ_20!E16/ТАБ_20!B16*1000,0) -> 667 | G17: =ROUND(ТАБ_20!F16/ТАБ_20!C16*1000,0) -> 596
... A101: Чукотский автономный округ | B101: 7.2 | C101: 7.2 | D101: 4.9 | E101: 4.8 | F101: =ROUND(ТАБ_20!E100/ТАБ_20!B100*1000,0) -> 686 | G101: =ROUND(ТАБ_20!F100/ТАБ_20!C100*1000,0) -> 671
B104: ЗАМЕСТИТЕЛЬ РУКОВОДИТЕЛЯ ФЕДЕРАЛЬНОЙ
B105: СЛУЖБЫ ГОСУДАРСТВЕННОЙ СТАТИСТИКИ | F105: П.А. СМЕЛОВ
